<?xml version="1.0" ?>
<!-- =================================================================================== -->
<!-- |    This document was autogenerated by xacro from arx5_description.urdf.xacro    | -->
<!-- |    EDITING THIS FILE BY HAND IS NOT RECOMMENDED                                 | -->
<!-- =================================================================================== -->
<!-- This URDF was automatically created by SolidWorks to URDF Exporter! Originally created by Stephen Brawner (brawner@gmail.com) 
     Commit Version: 1.6.0-4-g7f85cfe  Build Version: 1.6.7995.38578
     For more information, please see http://wiki.ros.org/sw_urdf_exporter -->
<robot name="arx5_description">
  <!-- <link name="footprint"/> -->
  <!--0.37810-->
  <!--    <xacro:property name="track" value="0.3426" />
    <xacro:property name="wheelbase" value="0.3181"/>
    <xacro:property name="wheel_vertical_offset" value="-0.160000047342231" />-->
  <!-- Base link -->
  <link name="base_link">
    <visual>
      <origin rpy="1.57 0 0" xyz="0 0 0"/>
      <!--<origin xyz="0 0 0" rpy="0 0 0"/>-->
      <geometry>
        <mesh filename="package://tracer_description/meshes/tracer_base_link_no_wheel.dae"/>
        <!--<box size="${base_x_size} ${base_y_size} ${base_z_size}"/>-->
      </geometry>
    </visual>
    <collision>
      <!--origin
            xyz="-0.0145261552504705 0.0231316650320557 0.00586280190939592"
            rpy="0 0 0" /-->
      <origin rpy="1.57 0 0" xyz="0 0 0"/>
      <geometry>
        <mesh filename="package://tracer_description/meshes/tracer_base_link_no_wheel.dae"/>
        <!--<box size="${base_x_size} ${base_y_size} ${base_z_size}"/>-->
      </geometry>
    </collision>
  </link>
  <!-- <joint name="chassis_link_joint" type="fixed">
        <origin xyz="0 0 ${wheel_radius - wheel_vertical_offset}" rpy="0 0 0" />
        <parent link="base_link" />
        <child link="chassis_link" />
    </joint> -->
  <link name="inertial_link">
    <inertial>
      <!--mass value="44.3898489950015" /-->
      <mass value="132.3898489950015"/>
      <!-- <mass value="50" /> -->
      <!-- <origin xyz="-0.00065 -0.085 0.062" />
            <inertia ixx="0.6022" ixy="-0.02364" ixz="-0.1197" iyy="1.7386" iyz="-0.001544" izz="2.0296" /> -->
      <origin xyz="0.015 0.0231316650320557 0"/>
      <!--<origin
              xyz="-0.0145261552504705 0.0231316650320557 0.00586280190939592"
              rpy="0 0 0" />-->
      <inertia ixx="0.185196122711036" ixy="4.30144213829512E-08" ixz="5.81037523686401E-08" iyy="0.364893736238929" iyz="-0.000386720198091934" izz="0.223868521722778"/>
      <!--<inertia ixx="2.288641" ixy="0" ixz="0" iyy="5.103976" iyz="0" izz="3.431465" />-->
    </inertial>
  </link>
  <joint name="inertial_joint" type="fixed">
    <origin rpy="0 0 0" xyz="0 0 0"/>
    <parent link="base_link"/>
    <child link="inertial_link"/>
  </joint>
  <!-- For testing, hang the robot up in the air -->
  <!-- <link name="world" />
    <joint name="world_to_base_link=" type="fixed">
        <origin xyz="0 0 0.5" rpy="0 0 0" />
        <parent link="world"/>
        <child link="base_link"/>
    </joint> -->
  <link name="right_wheel_link">
    <!--<inertial>
                <mass value="3" />
                <origin
                        xyz="0.162297526351145 -0.159063056237197 -0.159999952657767"
                        rpy="0 0 0" />
                        <inertia ixx="0.7171" ixy="0" ixz="0" iyy="0.1361" iyz="0" izz="0.7171" />
                   </inertial>
            <visual>
                <origin xyz="0 0 0" rpy="0 0 0" />
                <geometry>
                    <mesh filename="package://tracer_description/meshes/wheel.dae" />
                </geometry>
            </visual>-->
    <inertial>
      <mass value="6"/>
      <origin xyz="0 0 0"/>
      <inertia ixx="0.7171" ixy="0" ixz="0" iyy="0.1361" iyz="0" izz="0.7171"/>
      <!--<inertia ixx="0" ixy="0" ixz="0" iyy="0" iyz="0" izz="0" />-->
    </inertial>
    <visual>
      <origin rpy="0 0 0" xyz="0 0 0"/>
      <geometry>
        <mesh filename="package://tracer_description/meshes/tracer_wheel.dae"/>
        <!--<cylinder length="0.0787019" radius="0.0457774"/>-->
      </geometry>
    </visual>
    <collision>
      <origin rpy="0 0 0" xyz="0 0 0"/>
      <geometry>
        <mesh filename="package://tracer_description/meshes/tracer_wheel.dae"/>
        <!--<cylinder length="0.0787019" radius="0.0457774"/>-->
      </geometry>
    </collision>
  </link>
  <joint name="right_wheel" type="continuous">
    <!--<origin
                  xyz="0.14547 0.20835 -0.07424"
                  rpy="0 1.57 0" />-->
    <parent link="base_link"/>
    <child link="right_wheel_link"/>
    <origin rpy="0 0 0" xyz="0 -0.17 -0.082"/>
    <axis rpy="0 0 0" xyz="0 1 0"/>
  </joint>
  <link name="left_wheel_link">
    <!--<inertial>
            <mass value="3" />
                <origin
                        xyz="0.162297526351148 0.159063056237198 -0.160000047342231"
                        rpy="0 0 0" />
                        <inertia ixx="0.7171" ixy="0" ixz="0" iyy="0.1361" iyz="0" izz="0.7171" />
            </inertial>
            <visual>
                <origin xyz="0 0 0" rpy="0 0 0" />
                <geometry>
                    <mesh filename="package://tracer_description/meshes/wheel.dae" />
                </geometry>
            </visual>-->
    <inertial>
      <mass value="6"/>
      <origin xyz="0 0 0"/>
      <inertia ixx="0.7171" ixy="0" ixz="0" iyy="0.1361" iyz="0" izz="0.7171"/>
      <!--<inertia ixx="0" ixy="0" ixz="0" iyy="0" iyz="0" izz="0" />-->
    </inertial>
    <visual>
      <origin rpy="0 0 0" xyz="0 0 0"/>
      <geometry>
        <mesh filename="package://tracer_description/meshes/tracer_wheel.dae"/>
        <!--<cylinder length="0.0787019" radius="0.0457774"/>-->
      </geometry>
    </visual>
    <collision>
      <origin rpy="0 0 0" xyz="0 0 0"/>
      <geometry>
        <mesh filename="package://tracer_description/meshes/tracer_wheel.dae"/>
        <!--<cylinder length="0.0787019" radius="0.0457774"/>-->
      </geometry>
    </collision>
  </link>
  <joint name="left_wheel" type="continuous">
    <!--<origin
                  xyz="-0.17453 0.20835 -0.07424"
                  rpy="0 -1.57 0" />-->
    <parent link="base_link"/>
    <child link="left_wheel_link"/>
    <origin rpy="3.14 0 0" xyz="0 0.17 -0.082"/>
    <axis rpy="0 0 0" xyz="0 1 0"/>
  </joint>
  <!--tracer castor wheel-->
  <link name="fl_castor_link">
    <inertial>
      <mass value="1"/>
      <origin xyz="0 0 0"/>
      <inertia ixx="0.7171" ixy="0" ixz="0" iyy="0.1361" iyz="0" izz="0.7171"/>
    </inertial>
    <visual>
      <geometry>
        <!--<cylinder length="${castor_length}" radius="${castor_radius}"/>-->
        <mesh filename="package://tracer_description/meshes/castor_joint.dae"/>
      </geometry>
      <!--<material name="black">
                        <color rgba="255 255 255 1"/>
                   </material>-->
    </visual>
    <!--<collision>
              <origin
                xyz="0 0 0"
                rpy="0 0 0" />
              <geometry>
                <cylinder length="${castor_length}" radius="${castor_radius}"/>
                <mesh filename="package://tracer_description/meshes/castor_joint.dae" />
              </geometry>
            </collision>-->
  </link>
  <joint name="fl_castor_wheel" type="continuous">
    <origin rpy="-1.57 0 0" xyz="0.18955 0.17 -0.0380886"/>
    <parent link="base_link"/>
    <child link="fl_castor_link"/>
    <axis rpy="0 0 0" xyz="0 1 0"/>
  </joint>
  <link name="fr_castor_link">
    <inertial>
      <mass value="1"/>
      <origin xyz="0 0 0"/>
      <inertia ixx="0.7171" ixy="0" ixz="0" iyy="0.1361" iyz="0" izz="0.7171"/>
    </inertial>
    <visual>
      <geometry>
        <!--<cylinder length="${castor_length}" radius="${castor_radius}"/>-->
        <mesh filename="package://tracer_description/meshes/castor_joint.dae"/>
      </geometry>
      <!--<material name="black">
                        <color rgba="255 255 255 1"/>
                   </material>-->
    </visual>
    <!--<collision>
              <origin
                xyz="0 0 0"
                rpy="0 0 0" />
              <geometry>
                <cylinder length="${castor_length}" radius="${castor_radius}"/>
                <mesh filename="package://tracer_description/meshes/castor_joint.dae" />
              </geometry>
            </collision>-->
  </link>
  <joint name="fr_castor_wheel" type="continuous">
    <origin rpy="-1.57 0 0" xyz="0.18955 -0.17 -0.0380886"/>
    <parent link="base_link"/>
    <child link="fr_castor_link"/>
    <axis rpy="0 0 0" xyz="0 1 0"/>
  </joint>
  <link name="rr_castor_link">
    <inertial>
      <mass value="1"/>
      <origin xyz="0 0 0"/>
      <inertia ixx="0.7171" ixy="0" ixz="0" iyy="0.1361" iyz="0" izz="0.7171"/>
    </inertial>
    <visual>
      <geometry>
        <!--<cylinder length="${castor_length}" radius="${castor_radius}"/>-->
        <mesh filename="package://tracer_description/meshes/castor_joint.dae"/>
      </geometry>
      <!-- <material name="black">
                        <color rgba="255 255 255 1"/>
                   </material>-->
    </visual>
    <!--<collision>
              <origin
                xyz="0 0 0"
                rpy="0 0 0" />
              <geometry>
                <cylinder length="${castor_length}" radius="${castor_radius}"/>
                <mesh filename="package://tracer_description/meshes/castor_joint.dae" />
              </geometry>
            </collision>-->
  </link>
  <joint name="rr_castor_wheel" type="continuous">
    <origin rpy="-1.57 0 0" xyz="-0.18955 -0.17 -0.0380886"/>
    <parent link="base_link"/>
    <child link="rr_castor_link"/>
    <axis rpy="0 0 0" xyz="0 1 0"/>
  </joint>
  <link name="rl_castor_link">
    <inertial>
      <mass value="1"/>
      <origin xyz="0 0 0"/>
      <inertia ixx="0.7171" ixy="0" ixz="0" iyy="0.1361" iyz="0" izz="0.7171"/>
    </inertial>
    <visual>
      <geometry>
        <!--<cylinder length="${castor_length}" radius="${castor_radius}"/>-->
        <mesh filename="package://tracer_description/meshes/castor_joint.dae"/>
      </geometry>
      <!--<material name="black">
                        <color rgba="255 255 255 1"/>
                   </material>-->
    </visual>
    <!-- <collision>
              <origin
                xyz="0 0 0"
                rpy="0 0 0" />
              <geometry>
                <cylinder length="${castor_length}" radius="${castor_radius}"/>
                <mesh filename="package://tracer_description/meshes/castor_joint.dae" />
              </geometry>
            </collision>-->
  </link>
  <joint name="rl_castor_wheel" type="continuous">
    <origin rpy="-1.57 0 0" xyz="-0.18955 0.17 -0.0380886"/>
    <parent link="base_link"/>
    <child link="rl_castor_link"/>
    <axis rpy="0 0 0" xyz="0 1 0"/>
  </joint>
  <link name="fl_wheel_link">
    <inertial>
      <mass value="1"/>
      <origin xyz="0 0 0"/>
      <inertia ixx="0.3131" ixy="0" ixz="0" iyy="0.3131" iyz="0" izz="0.1361"/>
      <!--<inertia ixx="0" ixy="0" ixz="0" iyy="0" iyz="0" izz="0" />-->
    </inertial>
    <visual>
      <geometry>
        <!--<cylinder length="0.04653" radius="0.036"/>-->
        <!--<sphere radius="0.0457774"/>-->
        <mesh filename="package://tracer_description/meshes/castor.dae"/>
      </geometry>
      <!--<material name="black">
                    <color rgba="255 255 255 1"/>
               </material>-->
    </visual>
    <collision>
      <origin rpy="0 0 0" xyz="0 0 0"/>
      <geometry>
        --&gt;
                
        <!--<cylinder length="0.04653" radius="0.036"/>-->
        <!--<cylinder length="0.0787019" radius="0.0457774"/>-->
        <!--<sphere radius="0.0457774"/>-->
        <mesh filename="package://tracer_description/meshes/castor.dae"/>
      </geometry>
    </collision>
  </link>
  <joint name="fl_wheel" type="continuous">
    <!--<origin
                  xyz="0.14547 0.20835 -0.07424"
                  rpy="0 1.57 0" />-->
    <parent link="fl_castor_link"/>
    <child link="fl_wheel_link"/>
    <dynamics damping="0.0" friction="0.0"/>
    <origin rpy="0 0 0" xyz="-0.0218084 0.067 0"/>
    <axis rpy="0 0 0" xyz="0 0 1"/>
  </joint>
  <link name="fr_wheel_link">
    <inertial>
      <mass value="1"/>
      <origin xyz="0 0 0"/>
      <inertia ixx="0.3131" ixy="0" ixz="0" iyy="0.3131" iyz="0" izz="0.1361"/>
      <!--<inertia ixx="0" ixy="0" ixz="0" iyy="0" iyz="0" izz="0" />-->
    </inertial>
    <visual>
      <geometry>
        <!--<cylinder length="0.04653" radius="0.036"/>-->
        <!--<sphere radius="0.0457774"/>-->
        <mesh filename="package://tracer_description/meshes/castor.dae"/>
      </geometry>
      <!--<material name="black">
                   <color rgba="255 255 255 1"/>
                   </material>-->
    </visual>
    <collision>
      <origin rpy="0 0 0" xyz="0 0 0"/>
      <geometry>
        --&gt;
                
        <!--<cylinder length="0.04653" radius="0.036"/>-->
        <!--<cylinder length="0.0787019" radius="0.0457774"/>-->
        <!--<sphere radius="0.0457774"/>-->
        <mesh filename="package://tracer_description/meshes/castor.dae"/>
      </geometry>
    </collision>
  </link>
  <joint name="fr_wheel" type="continuous">
    <!--<origin
                  xyz="0.14547 0.20835 -0.07424"
                  rpy="0 1.57 0" />-->
    <parent link="fr_castor_link"/>
    <child link="fr_wheel_link"/>
    <dynamics damping="0.0" friction="0.0"/>
    <origin rpy="0 0 0" xyz="-0.0218084 0.067 0"/>
    <axis rpy="0 0 0" xyz="0 0 1"/>
  </joint>
  <link name="rr_wheel_link">
    <inertial>
      <mass value="1"/>
      <origin xyz="0 0 0"/>
      <inertia ixx="0.3131" ixy="0" ixz="0" iyy="0.3131" iyz="0" izz="0.1361"/>
      <!--<inertia ixx="0" ixy="0" ixz="0" iyy="0" iyz="0" izz="0" />-->
    </inertial>
    <visual>
      <geometry>
        <!--<cylinder length="0.04653" radius="0.036"/>-->
        <!--<sphere radius="0.0457774"/>-->
        <mesh filename="package://tracer_description/meshes/castor.dae"/>
      </geometry>
      <!--<material name="black">
                        <color rgba="255 255 255 1"/>
                   </material>-->
    </visual>
    <collision>
      <origin rpy="0 0 0" xyz="0 0 0"/>
      <geometry>
        <!--<mesh filename="package://tracer_description/meshes/wheel.dae" />-->
        <!--<cylinder length="0.04653" radius="0.036"/>-->
        <!-- <sphere radius="0.0457774"/>-->
        <mesh filename="package://tracer_description/meshes/castor.dae"/>
      </geometry>
    </collision>
  </link>
  <joint name="rr_wheel" type="continuous">
    <!--<origin
                  xyz="0.14547 0.20835 -0.07424"
                  rpy="0 1.57 0" />-->
    <parent link="rr_castor_link"/>
    <child link="rr_wheel_link"/>
    <dynamics damping="0.0" friction="0.0"/>
    <origin rpy="0 0 0" xyz="-0.0218084 0.067 0"/>
    <axis rpy="0 0 0" xyz="0 0 1"/>
  </joint>
  <link name="rl_wheel_link">
    <inertial>
      <mass value="1"/>
      <origin xyz="0 0 0"/>
      <inertia ixx="0.3131" ixy="0" ixz="0" iyy="0.3131" iyz="0" izz="0.1361"/>
      <!--<inertia ixx="0" ixy="0" ixz="0" iyy="0" iyz="0" izz="0" />-->
    </inertial>
    <visual>
      <geometry>
        <!--<cylinder length="0.04653" radius="0.036"/>-->
        <!--<sphere radius="0.0457774"/>-->
        <mesh filename="package://tracer_description/meshes/castor.dae"/>
      </geometry>
      <!--<material name="black">
                        <color rgba="255 255 255 1"/>
                   </material>-->
    </visual>
    <collision>
      <origin rpy="0 0 0" xyz="0 0 0"/>
      <geometry>
        <!--<cylinder length="0.04653" radius="0.036"/>-->
        <!--<cylinder length="0.0787019" radius="0.0457774"/>-->
        <!--<sphere radius="0.0457774"/>-->
        <mesh filename="package://tracer_description/meshes/castor.dae"/>
      </geometry>
    </collision>
  </link>
  <joint name="rl_wheel" type="continuous">
    <!--<origin
                  xyz="0.14547 0.20835 -0.07424"
                  rpy="0 1.57 0" />-->
    <parent link="rl_castor_link"/>
    <child link="rl_wheel_link"/>
    <dynamics damping="0.0" friction="0.0"/>
    <origin rpy="0 0 0" xyz="-0.0218084 0.067 0"/>
    <axis rpy="0 0 0" xyz="0 0 1"/>
  </joint>
  <!-- This file is a placeholder which is included by default from
       husky.urdf.xacro. If a robot is being customized and requires
       additional URDF, set the HUSKY_URDF_EXTRAS environment variable
       to the full path of the file you would like included. -->
  <!-- Additional definitions for simulation -->
  <!-- <gazebo reference="base_link">
        <material>Gazebo/Grey</material>
    </gazebo> -->
  <transmission name="right_wheel_trans" type="SimpleTransmission">
    <type>transmission_interface/SimpleTransmission</type>
    <actuator name="right_wheel_motor">
      <mechanicalReduction>1</mechanicalReduction>
    </actuator>
    <joint name="right_wheel">
      <hardwareInterface>hardware_interface/VelocityJointInterface</hardwareInterface>
    </joint>
  </transmission>
  <transmission name="left_wheel_trans" type="SimpleTransmission">
    <type>transmission_interface/SimpleTransmission</type>
    <actuator name="left_wheel_motor">
      <mechanicalReduction>1</mechanicalReduction>
    </actuator>
    <joint name="left_wheel">
      <hardwareInterface>hardware_interface/VelocityJointInterface</hardwareInterface>
    </joint>
  </transmission>
  <transmission name="fl_wheel_trans" type="SimpleTransmission">
    <type>transmission_interface/SimpleTransmission</type>
    <actuator name="fl_wheel_motor">
      <mechanicalReduction>1</mechanicalReduction>
    </actuator>
    <joint name="fl_wheel">
      <hardwareInterface>hardware_interface/VelocityJointInterface</hardwareInterface>
    </joint>
  </transmission>
  <transmission name="fr_wheel_trans" type="SimpleTransmission">
    <type>transmission_interface/SimpleTransmission</type>
    <actuator name="fr_wheel_motor">
      <mechanicalReduction>1</mechanicalReduction>
    </actuator>
    <joint name="fr_wheel">
      <hardwareInterface>hardware_interface/VelocityJointInterface</hardwareInterface>
    </joint>
  </transmission>
  <transmission name="rr_wheel_trans" type="SimpleTransmission">
    <type>transmission_interface/SimpleTransmission</type>
    <actuator name="rr_wheel_motor">
      <mechanicalReduction>1</mechanicalReduction>
    </actuator>
    <joint name="rr_wheel">
      <hardwareInterface>hardware_interface/VelocityJointInterface</hardwareInterface>
    </joint>
  </transmission>
  <transmission name="rl_wheel_trans" type="SimpleTransmission">
    <type>transmission_interface/SimpleTransmission</type>
    <actuator name="rl_wheel_motor">
      <mechanicalReduction>1</mechanicalReduction>
    </actuator>
    <joint name="rl_wheel">
      <hardwareInterface>hardware_interface/VelocityJointInterface</hardwareInterface>
    </joint>
  </transmission>
  <transmission name="fl_castor_wheel_trans" type="SimpleTransmission">
    <type>transmission_interface/SimpleTransmission</type>
    <actuator name="fl_castor_wheel_motor">
      <mechanicalReduction>1</mechanicalReduction>
    </actuator>
    <joint name="fl_castor_wheel">
      <hardwareInterface>hardware_interface/VelocityJointInterface</hardwareInterface>
    </joint>
  </transmission>
  <transmission name="fr_castor_wheel_trans" type="SimpleTransmission">
    <type>transmission_interface/SimpleTransmission</type>
    <actuator name="fr_castor_wheel_motor">
      <mechanicalReduction>1</mechanicalReduction>
    </actuator>
    <joint name="fr_castor_wheel">
      <hardwareInterface>hardware_interface/VelocityJointInterface</hardwareInterface>
    </joint>
  </transmission>
  <transmission name="rr_castor_wheel_trans" type="SimpleTransmission">
    <type>transmission_interface/SimpleTransmission</type>
    <actuator name="rr_castor_wheel_motor">
      <mechanicalReduction>1</mechanicalReduction>
    </actuator>
    <joint name="rr_castor_wheel">
      <hardwareInterface>hardware_interface/VelocityJointInterface</hardwareInterface>
    </joint>
  </transmission>
  <transmission name="rl_castor_wheel_trans" type="SimpleTransmission">
    <type>transmission_interface/SimpleTransmission</type>
    <actuator name="rl_castor_wheel_motor">
      <mechanicalReduction>1</mechanicalReduction>
    </actuator>
    <joint name="rl_castor_wheel">
      <hardwareInterface>hardware_interface/VelocityJointInterface</hardwareInterface>
    </joint>
  </transmission>
  <!-- Controller configurations -->
  <gazebo>
    <plugin filename="libgazebo_ros_control.so" name="gazebo_ros_control">
      <robotNamespace>/</robotNamespace>
    </plugin>
  </gazebo>
  <!-- kp spring constant, kd damping constant -->
  <!-- <gazebo>
        <mu1 value="1.0"/>
        <mu2 value="0.9"/>
        <kp value="10000000.0" />
        <kd value="1.0" />
        <fdir1 value="1 0 0"/>
        <minDepth value="0.001" />
        <maxContacts value="64"/>
    </gazebo> -->
  <gazebo reference="left_wheel_link">
    <mu1>1.0</mu1>
    <mu2>0.99</mu2>
    <kp>10000000.0</kp>
    <kd>1.0</kd>
    <minDepth>0.001</minDepth>
    <maxVel>0.1</maxVel>
    <fdir1>1 0 0</fdir1>
  </gazebo>
  <gazebo reference="right_wheel_link">
    <mu1>1.0</mu1>
    <mu2>0.99</mu2>
    <kp>10000000.0</kp>
    <kd>1.0</kd>
    <minDepth>0.001</minDepth>
    <maxVel>0.1</maxVel>
    <fdir1>1 0 0</fdir1>
  </gazebo>
  <gazebo reference="fl_wheel_link">
    <mu1>0.2</mu1>
    <mu2>0.2</mu2>
    <kp>100000.0</kp>
    <kd>1.0</kd>
    <minDepth>0.001</minDepth>
    <maxVel>0.1</maxVel>
    <fdir1>1 0 0</fdir1>
  </gazebo>
  <gazebo reference="fr_wheel_link">
    <mu1>0.2</mu1>
    <mu2>0.2</mu2>
    <kp>100000.0</kp>
    <kd>1.0</kd>
    <minDepth>0.001</minDepth>
    <maxVel>0.1</maxVel>
    <fdir1>1 0 0</fdir1>
  </gazebo>
  <gazebo reference="rr_wheel_link">
    <mu1>0.2</mu1>
    <mu2>0.2</mu2>
    <kp>100000.0</kp>
    <kd>1.0</kd>
    <minDepth>0.001</minDepth>
    <maxVel>0.1</maxVel>
    <fdir1>1 0 0</fdir1>
  </gazebo>
  <gazebo reference="rl_wheel_link">
    <mu1>0.2</mu1>
    <mu2>0.2</mu2>
    <kp>100000.0</kp>
    <kd>1.0</kd>
    <minDepth>0.001</minDepth>
    <maxVel>0.1</maxVel>
    <fdir1>1 0 0</fdir1>
  </gazebo>
  <!-- <gazebo>
        <plugin name="skid_steer_drive_controller" filename="libgazebo_ros_skid_steer_drive.so">
            <updateRate>100.0</updateRate>
            <robotNamespace></robotNamespace>
            <leftFrontJoint>left_wheel</leftFrontJoint>
            <rightFrontJoint>right_wheel</rightFrontJoint>
            <wheelSeparation>2</wheelSeparation>
            <wheelDiameter>0.32918</wheelDiameter>
            <robotBaseFrame>base_link</robotBaseFrame>
            <torque>1000</torque>
            <commandTopic>cmd_vel</commandTopic>
            <broadcastTF>true</broadcastTF>
            <odometryTopic>odom</odometryTopic>
            <odometryFrame>odom</odometryFrame>
            <covariance_x>0.000100</covariance_x>
            <covariance_y>0.000100</covariance_y>
            <covariance_yaw>0.010000</covariance_yaw>
        </plugin>
    </gazebo> -->
  <!-- <gazebo>
        <plugin name="object_controller" filename="libgazebo_ros_planar_move.so">
            <commandTopic>cmd_vel</commandTopic>
            <odometryTopic>odom</odometryTopic>
            <odometryFrame>odom</odometryFrame>
            <odometryRate>20.0</odometryRate>
            <robotBaseFrame>base_footprint</robotBaseFrame>
        </plugin>
    </gazebo> -->
  <link name="livox_base">
    <inertial>
      <mass value="0.1"/>
      <inertia ixx="0.01" ixy="0" ixz="0" iyy="0.01" iyz="0" izz="0.01"/>
    </inertial>
    <visual>
      <origin rpy="1.57 0 3.14" xyz="0.00 0 0.0"/>
      <geometry>
        <mesh filename="package://livox_laser_simulation/meshes/livox_mid360.dae" scale="0.001 0.001 0.001">
          </mesh>
      </geometry>
    </visual>
    <collision>
      <origin rpy="1.57 0 3.14" xyz="0 0 0"/>
      <geometry>
        <mesh filename="package://livox_laser_simulation/meshes/livox_mid360.dae" scale="0.001 0.001 0.001"> 
        </mesh>
      </geometry>
    </collision>
  </link>
  <link name="livox">
    <inertial>
      <mass value="0.1"/>
      <inertia ixx="0.01" ixy="0" ixz="0" iyy="0.01" iyz="0" izz="0.01"/>
    </inertial>
  </link>
  <joint name="livox_to_livox_base_joint" type="fixed">
    <origin rpy="0 0 0" xyz="0.0 0.0 0.03"/>
    <parent link="livox_base"/>
    <child link="livox"/>
    <axis xyz="0 0 0"/>
  </joint>
  <gazebo reference="livox">
    <sensor name="livox" type="ray">
      <pose>0 0 0 0 0 0</pose>
      <visualize>True</visualize>
      <update_rate>10</update_rate>
      <!-- This ray plgin is only for visualization. -->
      <plugin filename="liblivox_laser_simulation.so" name="gazebo_ros_laser_controller">
        <ray>
          <scan>
            <horizontal>
              <samples>100</samples>
              <resolution>1</resolution>
              <min_angle>0</min_angle>
              <max_angle>6.28318</max_angle>
            </horizontal>
            <vertical>
              <samples>360</samples>
              <resolution>1</resolution>
              <min_angle>-0.12601266555555554</min_angle>
              <max_angle>0.9637699988888888</max_angle>
            </vertical>
          </scan>
          <range>
            <min>0.1</min>
            <max>200.0</max>
            <resolution>0.002</resolution>
          </range>
          <noise>
            <type>gaussian</type>
            <mean>0.0</mean>
            <stddev>0.01</stddev>
          </noise>
        </ray>
        <visualize>True</visualize>
        <samples>24000</samples>
        <downsample>1</downsample>
        <csv_file_name>package://livox_laser_simulation/scan_mode/mid360.csv</csv_file_name>
        <ros_topic>scan</ros_topic>
      </plugin>
    </sensor>
  </gazebo>
  <!-- <xacro:include filename="$(find livox_laser_simulation)/urdf/standardrobots_oasis300.xacro"/>
  <xacro:link_oasis name="oasis"/> -->
  <!-- INTEL REALSENSE D435 -->
  <!-- INTEL REALSENSE R200 -->
  <link name="footprint">
    </link>
  <link name="robot::footprint">
    </link>
  <!-- camera body, with origin at bottom screw mount -->
  <joint name="camera_l_joint" type="fixed">
    <origin rpy="0 0 0 " xyz="0.06 0 0.06"/>
    <parent link="fl_link6"/>
    <child link="camera_l_bottom_screw_frame"/>
  </joint>
  <link name="camera_l_bottom_screw_frame"/>
  <joint name="camera_l_link_joint" type="fixed">
    <origin rpy="0 0 0" xyz="0 0.0175 0.0125"/>
    <parent link="camera_l_bottom_screw_frame"/>
    <child link="camera_l_link"/>
  </joint>
  <link name="camera_l_link">
    <visual>
      <origin rpy="1.5707963267948966 0 1.5707963267948966" xyz="0.0149 -0.0175 0"/>
      <geometry>
        <mesh filename="package://realsense_ros_gazebo/meshes/realsense_d435.stl"/>
      </geometry>
    </visual>
    <collision>
      <origin rpy="0 0 0" xyz="0 -0.0175 0"/>
      <geometry>
        <box size="0.02505 0.09 0.025"/>
      </geometry>
    </collision>
    <inertial>
      <mass value="0.564"/>
      <origin rpy="0 0 0" xyz="0 -0.0175 0"/>
      <inertia ixx="0.000410075" ixy="0" ixz="0" iyy="5.8867617499999996e-05" iyz="0" izz="5.8867617499999996e-05"/>
    </inertial>
  </link>
  <!-- camera depth joints and links -->
  <joint name="camera_l_depth_joint" type="fixed">
    <origin rpy="0 0 0" xyz="0 0 0"/>
    <parent link="camera_l_link"/>
    <child link="camera_l_depth_frame"/>
  </joint>
  <link name="camera_l_depth_frame"/>
  <joint name="camera_l_depth_optical_joint" type="fixed">
    <origin rpy="-1.5707963267948966 0 -1.5707963267948966" xyz="0 0 0"/>
    <parent link="camera_l_depth_frame"/>
    <child link="camera_l_depth_optical_frame"/>
  </joint>
  <link name="camera_l_depth_optical_frame"/>
  <!-- camera left IR joints and links -->
  <joint name="camera_l_left_ir_joint" type="fixed">
    <origin rpy="0 0 0" xyz="0 0.0 0"/>
    <parent link="camera_l_depth_frame"/>
    <child link="camera_l_left_ir_frame"/>
  </joint>
  <link name="camera_l_left_ir_frame"/>
  <joint name="camera_l_left_ir_optical_joint" type="fixed">
    <origin rpy="-1.5707963267948966 0 -1.5707963267948966" xyz="0 0 0"/>
    <parent link="camera_l_left_ir_frame"/>
    <child link="camera_l_left_ir_optical_frame"/>
  </joint>
  <link name="camera_l_left_ir_optical_frame"/>
  <!-- camera right IR joints and links -->
  <joint name="camera_l_right_ir_joint" type="fixed">
    <origin rpy="0 0 0" xyz="0 -0.05 0"/>
    <parent link="camera_l_depth_frame"/>
    <child link="camera_l_right_ir_frame"/>
  </joint>
  <link name="camera_l_right_ir_frame"/>
  <joint name="camera_l_right_ir_optical_joint" type="fixed">
    <origin rpy="-1.5707963267948966 0 -1.5707963267948966" xyz="0 0 0"/>
    <parent link="camera_l_right_ir_frame"/>
    <child link="camera_l_right_ir_optical_frame"/>
  </joint>
  <link name="camera_l_right_ir_optical_frame"/>
  <!-- camera color joints and links -->
  <joint name="camera_l_color_joint" type="fixed">
    <origin rpy="0 0 0" xyz="0 0.015 0"/>
    <parent link="camera_l_depth_frame"/>
    <child link="camera_l_color_frame"/>
  </joint>
  <link name="camera_l_color_frame"/>
  <joint name="camera_l_color_optical_joint" type="fixed">
    <origin rpy="-1.5707963267948966 0 -1.5707963267948966" xyz="0 0 0"/>
    <parent link="camera_l_color_frame"/>
    <child link="camera_l_color_optical_frame"/>
  </joint>
  <link name="camera_l_color_optical_frame"/>
  <!-- gazebo plugin -->
  <gazebo reference="camera_l_link">
    <self_collide>0</self_collide>
    <enable_wind>0</enable_wind>
    <kinematic>0</kinematic>
    <gravity>1</gravity>
    <mu2>1</mu2>
    <fdir1>0 0 0</fdir1>
    <kp>1e+13</kp>
    <kd>1</kd>
    <sensor name="camera_l_color" type="camera">
      <camera name="camera_l">
        <horizontal_fov>1.2112585008840648</horizontal_fov>
        <image>
          <width>640</width>
          <height>480</height>
          <format>RGB_INT8</format>
        </image>
        <clip>
          <near>0.1</near>
          <far>100</far>
        </clip>
        <noise>
          <type>gaussian</type>
          <mean>0.0</mean>
          <stddev>0.007</stddev>
        </noise>
      </camera>
      <always_on>1</always_on>
      <update_rate>30</update_rate>
      <visualize>1</visualize>
    </sensor>
    <sensor name="camera_l_ired1" type="camera">
      <camera name="camera_l">
        <horizontal_fov>1.4870205226991688</horizontal_fov>
        <image>
          <width>1280</width>
          <height>720</height>
          <format>L_INT8</format>
        </image>
        <clip>
          <near>0.1</near>
          <far>100</far>
        </clip>
        <noise>
          <type>gaussian</type>
          <mean>0.0</mean>
          <stddev>0.05</stddev>
        </noise>
      </camera>
      <always_on>1</always_on>
      <update_rate>90</update_rate>
      <visualize>0</visualize>
    </sensor>
    <sensor name="camera_l_ired2" type="camera">
      <camera name="camera_l">
        <horizontal_fov>1.4870205226991688</horizontal_fov>
        <image>
          <width>1280</width>
          <height>720</height>
          <format>L_INT8</format>
        </image>
        <clip>
          <near>0.1</near>
          <far>100</far>
        </clip>
        <noise>
          <type>gaussian</type>
          <mean>0.0</mean>
          <stddev>0.05</stddev>
        </noise>
      </camera>
      <always_on>1</always_on>
      <update_rate>90</update_rate>
      <visualize>0</visualize>
    </sensor>
    <sensor name="camera_l_depth" type="depth">
      <camera name="camera_l">
        <horizontal_fov>1.4870205226991688</horizontal_fov>
        <image>
          <width>1280</width>
          <height>720</height>
        </image>
        <clip>
          <near>0.1</near>
          <far>100</far>
        </clip>
        <noise>
          <type>gaussian</type>
          <mean>0.0</mean>
          <stddev>0.100</stddev>
        </noise>
      </camera>
      <always_on>1</always_on>
      <update_rate>90</update_rate>
      <visualize>0</visualize>
    </sensor>
  </gazebo>
  <gazebo>
    <plugin filename="librealsense_gazebo_plugin.so" name="camera_l">
      <prefix>camera_l_</prefix>
      <depthUpdateRate>10</depthUpdateRate>
      <colorUpdateRate>10</colorUpdateRate>
      <infraredUpdateRate>10</infraredUpdateRate>
      <depthTopicName>depth/image_raw</depthTopicName>
      <depthCameraInfoTopicName>depth/camera_info</depthCameraInfoTopicName>
      <colorTopicName>color/image_raw</colorTopicName>
      <colorCameraInfoTopicName>color/camera_info</colorCameraInfoTopicName>
      <infrared1TopicName>infra1/image_raw</infrared1TopicName>
      <infrared1CameraInfoTopicName>infra1/camera_info</infrared1CameraInfoTopicName>
      <infrared2TopicName>infra2/image_raw</infrared2TopicName>
      <infrared2CameraInfoTopicName>infra2/camera_info</infrared2CameraInfoTopicName>
      <colorOpticalframeName>camera_l_color_optical_frame</colorOpticalframeName>
      <depthOpticalframeName>camera_l_depth_optical_frame</depthOpticalframeName>
      <infrared1OpticalframeName>camera_l_infrared1_optical_frame</infrared1OpticalframeName>
      <infrared2OpticalframeName>camera_l_infrared2_optical_frame</infrared2OpticalframeName>
      <rangeMinDepth>0.2</rangeMinDepth>
      <rangeMaxDepth>10.0</rangeMaxDepth>
      <pointCloud>false</pointCloud>
      <pointCloudTopicName>depth/color/points</pointCloudTopicName>
      <pointCloudCutoff>0.25</pointCloudCutoff>
      <pointCloudCutoffMax>9.0</pointCloudCutoffMax>
    </plugin>
  </gazebo>
  <!-- camera body, with origin at bottom screw mount -->
  <joint name="camera_r_joint" type="fixed">
    <origin rpy="0 0 0 " xyz="0.06 0 0.06"/>
    <parent link="fr_link6"/>
    <child link="camera_r_bottom_screw_frame"/>
  </joint>
  <link name="camera_r_bottom_screw_frame"/>
  <joint name="camera_r_link_joint" type="fixed">
    <origin rpy="0 0 0" xyz="0 0.0175 0.0125"/>
    <parent link="camera_r_bottom_screw_frame"/>
    <child link="camera_r_link"/>
  </joint>
  <link name="camera_r_link">
    <visual>
      <origin rpy="1.5707963267948966 0 1.5707963267948966" xyz="0.0149 -0.0175 0"/>
      <geometry>
        <mesh filename="package://realsense_ros_gazebo/meshes/realsense_d435.stl"/>
      </geometry>
    </visual>
    <collision>
      <origin rpy="0 0 0" xyz="0 -0.0175 0"/>
      <geometry>
        <box size="0.02505 0.09 0.025"/>
      </geometry>
    </collision>
    <inertial>
      <mass value="0.564"/>
      <origin rpy="0 0 0" xyz="0 -0.0175 0"/>
      <inertia ixx="0.000410075" ixy="0" ixz="0" iyy="5.8867617499999996e-05" iyz="0" izz="5.8867617499999996e-05"/>
    </inertial>
  </link>
  <!-- camera depth joints and links -->
  <joint name="camera_r_depth_joint" type="fixed">
    <origin rpy="0 0 0" xyz="0 0 0"/>
    <parent link="camera_r_link"/>
    <child link="camera_r_depth_frame"/>
  </joint>
  <link name="camera_r_depth_frame"/>
  <joint name="camera_r_depth_optical_joint" type="fixed">
    <origin rpy="-1.5707963267948966 0 -1.5707963267948966" xyz="0 0 0"/>
    <parent link="camera_r_depth_frame"/>
    <child link="camera_r_depth_optical_frame"/>
  </joint>
  <link name="camera_r_depth_optical_frame"/>
  <!-- camera left IR joints and links -->
  <joint name="camera_r_left_ir_joint" type="fixed">
    <origin rpy="0 0 0" xyz="0 0.0 0"/>
    <parent link="camera_r_depth_frame"/>
    <child link="camera_r_left_ir_frame"/>
  </joint>
  <link name="camera_r_left_ir_frame"/>
  <joint name="camera_r_left_ir_optical_joint" type="fixed">
    <origin rpy="-1.5707963267948966 0 -1.5707963267948966" xyz="0 0 0"/>
    <parent link="camera_r_left_ir_frame"/>
    <child link="camera_r_left_ir_optical_frame"/>
  </joint>
  <link name="camera_r_left_ir_optical_frame"/>
  <!-- camera right IR joints and links -->
  <joint name="camera_r_right_ir_joint" type="fixed">
    <origin rpy="0 0 0" xyz="0 -0.05 0"/>
    <parent link="camera_r_depth_frame"/>
    <child link="camera_r_right_ir_frame"/>
  </joint>
  <link name="camera_r_right_ir_frame"/>
  <joint name="camera_r_right_ir_optical_joint" type="fixed">
    <origin rpy="-1.5707963267948966 0 -1.5707963267948966" xyz="0 0 0"/>
    <parent link="camera_r_right_ir_frame"/>
    <child link="camera_r_right_ir_optical_frame"/>
  </joint>
  <link name="camera_r_right_ir_optical_frame"/>
  <!-- camera color joints and links -->
  <joint name="camera_r_color_joint" type="fixed">
    <origin rpy="0 0 0" xyz="0 0.015 0"/>
    <parent link="camera_r_depth_frame"/>
    <child link="camera_r_color_frame"/>
  </joint>
  <link name="camera_r_color_frame"/>
  <joint name="camera_r_color_optical_joint" type="fixed">
    <origin rpy="-1.5707963267948966 0 -1.5707963267948966" xyz="0 0 0"/>
    <parent link="camera_r_color_frame"/>
    <child link="camera_r_color_optical_frame"/>
  </joint>
  <link name="camera_r_color_optical_frame"/>
  <!-- gazebo plugin -->
  <gazebo reference="camera_r_link">
    <self_collide>0</self_collide>
    <enable_wind>0</enable_wind>
    <kinematic>0</kinematic>
    <gravity>1</gravity>
    <mu2>1</mu2>
    <fdir1>0 0 0</fdir1>
    <kp>1e+13</kp>
    <kd>1</kd>
    <sensor name="camera_r_color" type="camera">
      <camera name="camera_r">
        <horizontal_fov>1.2112585008840648</horizontal_fov>
        <image>
          <width>640</width>
          <height>480</height>
          <format>RGB_INT8</format>
        </image>
        <clip>
          <near>0.1</near>
          <far>100</far>
        </clip>
        <noise>
          <type>gaussian</type>
          <mean>0.0</mean>
          <stddev>0.007</stddev>
        </noise>
      </camera>
      <always_on>1</always_on>
      <update_rate>30</update_rate>
      <visualize>1</visualize>
    </sensor>
    <sensor name="camera_r_ired1" type="camera">
      <camera name="camera_r">
        <horizontal_fov>1.4870205226991688</horizontal_fov>
        <image>
          <width>1280</width>
          <height>720</height>
          <format>L_INT8</format>
        </image>
        <clip>
          <near>0.1</near>
          <far>100</far>
        </clip>
        <noise>
          <type>gaussian</type>
          <mean>0.0</mean>
          <stddev>0.05</stddev>
        </noise>
      </camera>
      <always_on>1</always_on>
      <update_rate>90</update_rate>
      <visualize>0</visualize>
    </sensor>
    <sensor name="camera_r_ired2" type="camera">
      <camera name="camera_r">
        <horizontal_fov>1.4870205226991688</horizontal_fov>
        <image>
          <width>1280</width>
          <height>720</height>
          <format>L_INT8</format>
        </image>
        <clip>
          <near>0.1</near>
          <far>100</far>
        </clip>
        <noise>
          <type>gaussian</type>
          <mean>0.0</mean>
          <stddev>0.05</stddev>
        </noise>
      </camera>
      <always_on>1</always_on>
      <update_rate>90</update_rate>
      <visualize>0</visualize>
    </sensor>
    <sensor name="camera_r_depth" type="depth">
      <camera name="camera_r">
        <horizontal_fov>1.4870205226991688</horizontal_fov>
        <image>
          <width>1280</width>
          <height>720</height>
        </image>
        <clip>
          <near>0.1</near>
          <far>100</far>
        </clip>
        <noise>
          <type>gaussian</type>
          <mean>0.0</mean>
          <stddev>0.100</stddev>
        </noise>
      </camera>
      <always_on>1</always_on>
      <update_rate>90</update_rate>
      <visualize>0</visualize>
    </sensor>
  </gazebo>
  <gazebo>
    <plugin filename="librealsense_gazebo_plugin.so" name="camera_r">
      <prefix>camera_r_</prefix>
      <depthUpdateRate>10</depthUpdateRate>
      <colorUpdateRate>10</colorUpdateRate>
      <infraredUpdateRate>10</infraredUpdateRate>
      <depthTopicName>depth/image_raw</depthTopicName>
      <depthCameraInfoTopicName>depth/camera_info</depthCameraInfoTopicName>
      <colorTopicName>color/image_raw</colorTopicName>
      <colorCameraInfoTopicName>color/camera_info</colorCameraInfoTopicName>
      <infrared1TopicName>infra1/image_raw</infrared1TopicName>
      <infrared1CameraInfoTopicName>infra1/camera_info</infrared1CameraInfoTopicName>
      <infrared2TopicName>infra2/image_raw</infrared2TopicName>
      <infrared2CameraInfoTopicName>infra2/camera_info</infrared2CameraInfoTopicName>
      <colorOpticalframeName>camera_r_color_optical_frame</colorOpticalframeName>
      <depthOpticalframeName>camera_r_depth_optical_frame</depthOpticalframeName>
      <infrared1OpticalframeName>camera_r_infrared1_optical_frame</infrared1OpticalframeName>
      <infrared2OpticalframeName>camera_r_infrared2_optical_frame</infrared2OpticalframeName>
      <rangeMinDepth>0.2</rangeMinDepth>
      <rangeMaxDepth>10.0</rangeMaxDepth>
      <pointCloud>false</pointCloud>
      <pointCloudTopicName>depth/color/points</pointCloudTopicName>
      <pointCloudCutoff>0.25</pointCloudCutoff>
      <pointCloudCutoffMax>9.0</pointCloudCutoffMax>
    </plugin>
  </gazebo>
  <!-- camera body, with origin at bottom screw mount -->
  <joint name="camera_f_joint" type="fixed">
    <origin rpy="0 0 0 " xyz="0.17 -0.01 0.84"/>
    <parent link="footprint"/>
    <child link="camera_f_bottom_screw_frame"/>
  </joint>
  <link name="camera_f_bottom_screw_frame"/>
  <joint name="camera_f_link_joint" type="fixed">
    <origin rpy="0 0 0" xyz="0 0.0175 0.0125"/>
    <parent link="camera_f_bottom_screw_frame"/>
    <child link="camera_f_link"/>
  </joint>
  <link name="camera_f_link">
    <visual>
      <origin rpy="1.5707963267948966 0 1.5707963267948966" xyz="0.0149 -0.0175 0"/>
      <geometry>
        <mesh filename="package://realsense_ros_gazebo/meshes/realsense_d435.stl"/>
      </geometry>
    </visual>
    <collision>
      <origin rpy="0 0 0" xyz="0 -0.0175 0"/>
      <geometry>
        <box size="0.02505 0.09 0.025"/>
      </geometry>
    </collision>
    <inertial>
      <mass value="0.564"/>
      <origin rpy="0 0 0" xyz="0 -0.0175 0"/>
      <inertia ixx="0.000410075" ixy="0" ixz="0" iyy="5.8867617499999996e-05" iyz="0" izz="5.8867617499999996e-05"/>
    </inertial>
  </link>
  <!-- camera depth joints and links -->
  <joint name="camera_f_depth_joint" type="fixed">
    <origin rpy="0 0 0" xyz="0 0 0"/>
    <parent link="camera_f_link"/>
    <child link="camera_f_depth_frame"/>
  </joint>
  <link name="camera_f_depth_frame"/>
  <joint name="camera_f_depth_optical_joint" type="fixed">
    <origin rpy="-1.5707963267948966 0 -1.5707963267948966" xyz="0 0 0"/>
    <parent link="camera_f_depth_frame"/>
    <child link="camera_f_depth_optical_frame"/>
  </joint>
  <link name="camera_f_depth_optical_frame"/>
  <!-- camera left IR joints and links -->
  <joint name="camera_f_left_ir_joint" type="fixed">
    <origin rpy="0 0 0" xyz="0 0.0 0"/>
    <parent link="camera_f_depth_frame"/>
    <child link="camera_f_left_ir_frame"/>
  </joint>
  <link name="camera_f_left_ir_frame"/>
  <joint name="camera_f_left_ir_optical_joint" type="fixed">
    <origin rpy="-1.5707963267948966 0 -1.5707963267948966" xyz="0 0 0"/>
    <parent link="camera_f_left_ir_frame"/>
    <child link="camera_f_left_ir_optical_frame"/>
  </joint>
  <link name="camera_f_left_ir_optical_frame"/>
  <!-- camera right IR joints and links -->
  <joint name="camera_f_right_ir_joint" type="fixed">
    <origin rpy="0 0 0" xyz="0 -0.05 0"/>
    <parent link="camera_f_depth_frame"/>
    <child link="camera_f_right_ir_frame"/>
  </joint>
  <link name="camera_f_right_ir_frame"/>
  <joint name="camera_f_right_ir_optical_joint" type="fixed">
    <origin rpy="-1.5707963267948966 0 -1.5707963267948966" xyz="0 0 0"/>
    <parent link="camera_f_right_ir_frame"/>
    <child link="camera_f_right_ir_optical_frame"/>
  </joint>
  <link name="camera_f_right_ir_optical_frame"/>
  <!-- camera color joints and links -->
  <joint name="camera_f_color_joint" type="fixed">
    <origin rpy="0 0 0" xyz="0 0.015 0"/>
    <parent link="camera_f_depth_frame"/>
    <child link="camera_f_color_frame"/>
  </joint>
  <link name="camera_f_color_frame"/>
  <joint name="camera_f_color_optical_joint" type="fixed">
    <origin rpy="-1.5707963267948966 0 -1.5707963267948966" xyz="0 0 0"/>
    <parent link="camera_f_color_frame"/>
    <child link="camera_f_color_optical_frame"/>
  </joint>
  <link name="camera_f_color_optical_frame"/>
  <!-- gazebo plugin -->
  <gazebo reference="camera_f_link">
    <self_collide>0</self_collide>
    <enable_wind>0</enable_wind>
    <kinematic>0</kinematic>
    <gravity>1</gravity>
    <mu2>1</mu2>
    <fdir1>0 0 0</fdir1>
    <kp>1e+13</kp>
    <kd>1</kd>
    <sensor name="camera_f_color" type="camera">
      <camera name="camera_f">
        <horizontal_fov>1.2112585008840648</horizontal_fov>
        <image>
          <width>640</width>
          <height>480</height>
          <format>RGB_INT8</format>
        </image>
        <clip>
          <near>0.1</near>
          <far>100</far>
        </clip>
        <noise>
          <type>gaussian</type>
          <mean>0.0</mean>
          <stddev>0.007</stddev>
        </noise>
      </camera>
      <always_on>1</always_on>
      <update_rate>30</update_rate>
      <visualize>1</visualize>
    </sensor>
    <sensor name="camera_f_ired1" type="camera">
      <camera name="camera_f">
        <horizontal_fov>1.4870205226991688</horizontal_fov>
        <image>
          <width>1280</width>
          <height>720</height>
          <format>L_INT8</format>
        </image>
        <clip>
          <near>0.1</near>
          <far>100</far>
        </clip>
        <noise>
          <type>gaussian</type>
          <mean>0.0</mean>
          <stddev>0.05</stddev>
        </noise>
      </camera>
      <always_on>1</always_on>
      <update_rate>90</update_rate>
      <visualize>0</visualize>
    </sensor>
    <sensor name="camera_f_ired2" type="camera">
      <camera name="camera_f">
        <horizontal_fov>1.4870205226991688</horizontal_fov>
        <image>
          <width>1280</width>
          <height>720</height>
          <format>L_INT8</format>
        </image>
        <clip>
          <near>0.1</near>
          <far>100</far>
        </clip>
        <noise>
          <type>gaussian</type>
          <mean>0.0</mean>
          <stddev>0.05</stddev>
        </noise>
      </camera>
      <always_on>1</always_on>
      <update_rate>90</update_rate>
      <visualize>0</visualize>
    </sensor>
    <sensor name="camera_f_depth" type="depth">
      <camera name="camera_f">
        <horizontal_fov>1.4870205226991688</horizontal_fov>
        <image>
          <width>1280</width>
          <height>720</height>
        </image>
        <clip>
          <near>0.1</near>
          <far>100</far>
        </clip>
        <noise>
          <type>gaussian</type>
          <mean>0.0</mean>
          <stddev>0.100</stddev>
        </noise>
      </camera>
      <always_on>1</always_on>
      <update_rate>90</update_rate>
      <visualize>0</visualize>
    </sensor>
  </gazebo>
  <gazebo>
    <plugin filename="librealsense_gazebo_plugin.so" name="camera_f">
      <prefix>camera_f_</prefix>
      <depthUpdateRate>10</depthUpdateRate>
      <colorUpdateRate>10</colorUpdateRate>
      <infraredUpdateRate>10</infraredUpdateRate>
      <depthTopicName>depth/image_raw</depthTopicName>
      <depthCameraInfoTopicName>depth/camera_info</depthCameraInfoTopicName>
      <colorTopicName>color/image_raw</colorTopicName>
      <colorCameraInfoTopicName>color/camera_info</colorCameraInfoTopicName>
      <infrared1TopicName>infra1/image_raw</infrared1TopicName>
      <infrared1CameraInfoTopicName>infra1/camera_info</infrared1CameraInfoTopicName>
      <infrared2TopicName>infra2/image_raw</infrared2TopicName>
      <infrared2CameraInfoTopicName>infra2/camera_info</infrared2CameraInfoTopicName>
      <colorOpticalframeName>camera_f_color_optical_frame</colorOpticalframeName>
      <depthOpticalframeName>camera_f_depth_optical_frame</depthOpticalframeName>
      <infrared1OpticalframeName>camera_f_infrared1_optical_frame</infrared1OpticalframeName>
      <infrared2OpticalframeName>camera_f_infrared2_optical_frame</infrared2OpticalframeName>
      <rangeMinDepth>0.2</rangeMinDepth>
      <rangeMaxDepth>10.0</rangeMaxDepth>
      <pointCloud>false</pointCloud>
      <pointCloudTopicName>depth/color/points</pointCloudTopicName>
      <pointCloudCutoff>0.25</pointCloudCutoff>
      <pointCloudCutoffMax>9.0</pointCloudCutoffMax>
    </plugin>
  </gazebo>
  <joint name="box_joint" type="fixed">
    <origin rpy="0 0 0" xyz="0 0 0.15"/>
    <parent link="footprint"/>
    <child link="base_link"/>
    <axis xyz="0 0 0"/>
  </joint>
  <joint name="livox_joint" type="fixed">
    <origin rpy="0 0 0" xyz="0.23 0 0.19"/>
    <parent link="footprint"/>
    <child link="livox_base"/>
    <axis xyz="0 0 0"/>
  </joint>
  <joint name="robot_footprint_joint" type="fixed">
    <origin rpy="0 0 0" xyz="0.18 0 0.29"/>
    <parent link="footprint"/>
    <child link="robot::footprint"/>
    <axis xyz="0 0 0"/>
  </joint>
  <link name="box1_Link">
    <inertial>
      <origin rpy="0 0 0" xyz="-0.17227 -0.0012276 0.023432"/>
      <mass value="0.00014994"/>
      <inertia ixx="0.012264" ixy="-9.2432E-06" ixz="0.0001761" iyy="0.0045226" iyz="-0.00063248" izz="0.016558"/>
    </inertial>
    <visual>
      <origin rpy="-0.05 0 0" xyz="0 0 0"/>
      <geometry>
        <mesh filename="package://aloha/meshes/box1_Link.STL"/>
      </geometry>
      <material name="">
        <color rgba="0.79216 0.81961 0.93333 1"/>
      </material>
    </visual>
    <collision>
      <origin rpy="-0.05 0 0" xyz="0 0 0"/>
      <geometry>
        <mesh filename="package://aloha/meshes/box1_Link.STL"/>
      </geometry>
    </collision>
  </link>
  <joint name="box1" type="fixed">
    <origin rpy="0 0 0" xyz="0 0 0.15"/>
    <parent link="footprint"/>
    <child link="box1_Link"/>
    <axis xyz="0 0 0"/>
  </joint>
  <link name="box2_Link">
    <inertial>
      <origin rpy="0 0 0" xyz="0.015107 -0.027922 0.00013672"/>
      <mass value="3.736"/>
      <inertia ixx="0.097545" ixy="-9.2609E-06" ixz="0.00015366" iyy="0.045841" iyz="-0.0020459" izz="0.084773"/>
    </inertial>
    <visual>
      <origin rpy="-0.05 0 0" xyz="0 0 0"/>
      <geometry>
        <mesh filename="package://aloha/meshes/box2_Link.STL"/>
      </geometry>
      <material name="">
        <color rgba="0.79216 0.81961 0.93333 1"/>
      </material>
    </visual>
    <collision>
      <origin rpy="-0.05 0 0" xyz="0 0 0"/>
      <geometry>
        <mesh filename="package://aloha/meshes/box2_Link.STL"/>
      </geometry>
    </collision>
  </link>
  <joint name="box2" type="fixed">
    <origin rpy="0 0 0" xyz="0 0 0"/>
    <parent link="box1_Link"/>
    <child link="box2_Link"/>
    <axis xyz="0 0 0"/>
  </joint>
  <!--***************************** front-left ****************************** -->
  <link name="fl_base_link">
    <inertial>
      <origin rpy="0 0 0" xyz="-2.9972E-05 3.056E-05 0.027301"/>
      <mass value="0.44038"/>
      <inertia ixx="0.00017" ixy="0.00000" ixz="0.00000" iyy="0.00018" iyz="0.00000" izz="0.00016"/>
    </inertial>
    <visual>
      <origin rpy="0 0 0" xyz="0 0 0"/>
      <geometry>
        <mesh filename="package://arx5_description/meshes/base_link.STL"/>
      </geometry>
      <material name="">
        <color rgba="0.75294 0.75294 0.75294 1"/>
      </material>
    </visual>
    <collision>
      <origin rpy="0 0 0" xyz="0 0 0"/>
      <geometry>
        <mesh filename="package://arx5_description/meshes/base_link.STL"/>
      </geometry>
    </collision>
  </link>
  <joint name="fl_base_joint" type="fixed">
    <origin rpy="0.0 0.0 0.0" xyz="0.233 0.3 0.7775"/>
    <parent link="footprint"/>
    <child link="fl_base_link"/>
    <axis xyz="0.0 0.0 1.0"/>
  </joint>
  <link name="fl_link1">
    <inertial>
      <origin rpy="0 0 0" xyz="0.00609525411893452 -0.00429681977500749 0.0179590247477389"/>
      <mass value="0.0608351104988555"/>
      <inertia ixx="0.00008" ixy="0.00000" ixz="0.00001" iyy="0.00003" iyz="0.00000" izz="0.00007"/>
    </inertial>
    <visual>
      <origin rpy="0 0 0" xyz="0 0 0"/>
      <geometry>
        <mesh filename="package://arx5_description/meshes/link1.STL"/>
      </geometry>
      <material name="">
        <color rgba="0.752941176470588 0.752941176470588 0.752941176470588 1"/>
      </material>
    </visual>
    <collision>
      <origin rpy="0 0 0" xyz="0 0 0"/>
      <geometry>
        <mesh filename="package://arx5_description/meshes/link1.STL"/>
      </geometry>
    </collision>
  </link>
  <joint name="fl_joint1" type="revolute">
    <origin rpy="0 0 0" xyz="0 0 0.0603"/>
    <parent link="fl_base_link"/>
    <child link="fl_link1"/>
    <axis xyz="0 0 1"/>
    <limit effort="100" lower="-10" upper="10" velocity="1000"/>
  </joint>
  <link name="fl_link2">
    <inertial>
      <origin rpy="0 0 0" xyz="-0.132382037190567 0.00220380675553821 0.000111790164679923"/>
      <mass value="1.0733279014126"/>
      <inertia ixx="0.00050" ixy="0.00000" ixz="-0.00004" iyy="0.01596" iyz="0.00000" izz="0.01602"/>
    </inertial>
    <visual>
      <origin rpy="0 0 0" xyz="0 0 0"/>
      <geometry>
        <mesh filename="package://arx5_description/meshes/link2.STL"/>
      </geometry>
      <material name="">
        <color rgba="0.752941176470588 0.752941176470588 0.752941176470588 1"/>
      </material>
    </visual>
    <collision>
      <origin rpy="0 0 0" xyz="0 0 0"/>
      <geometry>
        <mesh filename="package://arx5_description/meshes/link2.STL"/>
      </geometry>
    </collision>
  </link>
  <joint name="fl_joint2" type="revolute">
    <origin rpy="0 0 0" xyz="0.02 0 0.0402"/>
    <parent link="fl_link1"/>
    <child link="fl_link2"/>
    <axis xyz="0 1 0"/>
    <limit effort="100" lower="-10" upper="10" velocity="1000"/>
  </joint>
  <link name="fl_link3">
    <inertial>
      <origin rpy="0 0 0" xyz="0.187203287369961 -0.000305676361444925 -0.0514832866415513"/>
      <mass value="0.499404738025019"/>
      <inertia ixx="0.00033" ixy="-0.00006" ixz="-0.00039" iyy="0.00387" iyz="0.00001" izz="0.00383"/>
    </inertial>
    <visual>
      <origin rpy="0 0 0" xyz="0 0 0"/>
      <geometry>
        <mesh filename="package://arx5_description/meshes/link3.STL"/>
      </geometry>
      <material name="">
        <color rgba="0.752941176470588 0.752941176470588 0.752941176470588 1"/>
      </material>
    </visual>
    <collision>
      <origin rpy="0 0 0" xyz="0 0 0"/>
      <geometry>
        <mesh filename="package://arx5_description/meshes/link3.STL"/>
      </geometry>
    </collision>
  </link>
  <joint name="fl_joint3" type="revolute">
    <origin rpy="-3.1416 0 0" xyz="-0.264 0 0"/>
    <parent link="fl_link2"/>
    <child link="fl_link3"/>
    <axis xyz="0 1 0"/>
    <limit effort="100" lower="-10" upper="10" velocity="1000"/>
  </joint>
  <link name="fl_link4">
    <inertial>
      <origin rpy="0 0 0" xyz="0.0388884702662706 0.00295168681334743 -0.0353282735009622"/>
      <mass value="0.0809712553169999"/>
      <inertia ixx="0.00013" ixy="-0.00001" ixz="-0.00006" iyy="0.00016" iyz="0.00001" izz="0.00010"/>
    </inertial>
    <visual>
      <origin rpy="0 0 0" xyz="0 0 0"/>
      <geometry>
        <mesh filename="package://arx5_description/meshes/link4.STL"/>
      </geometry>
      <material name="">
        <color rgba="0.898039215686275 0.917647058823529 0.929411764705882 1"/>
      </material>
    </visual>
    <collision>
      <origin rpy="0 0 0" xyz="0 0 0"/>
      <geometry>
        <mesh filename="package://arx5_description/meshes/link4.STL"/>
      </geometry>
    </collision>
  </link>
  <joint name="fl_joint4" type="revolute">
    <origin rpy="0 0 0" xyz="0.245 0 -0.056"/>
    <parent link="fl_link3"/>
    <child link="fl_link4"/>
    <axis xyz="0 1 0"/>
    <limit effort="100" lower="-10" upper="10" velocity="1000"/>
  </joint>
  <link name="fl_link5">
    <inertial>
      <origin rpy="0 0 0" xyz="0.00289956909960302 3.15826689885766E-05 0.0526188859211408"/>
      <mass value="0.602357399313257"/>
      <inertia ixx="0.00072" ixy="0.00000" ixz="0.00005" iyy="0.00069" iyz="0.00000" izz="0.00021"/>
    </inertial>
    <visual>
      <origin rpy="0 0 0" xyz="0 0 0"/>
      <geometry>
        <mesh filename="package://arx5_description/meshes/link5.STL"/>
      </geometry>
      <material name="">
        <color rgba="0.752941176470588 0.752941176470588 0.752941176470588 1"/>
      </material>
    </visual>
    <collision>
      <origin rpy="0 0 0" xyz="0 0 0"/>
      <geometry>
        <mesh filename="package://arx5_description/meshes/link5.STL"/>
      </geometry>
    </collision>
  </link>
  <joint name="fl_joint5" type="revolute">
    <origin rpy="0 0 0" xyz="0.06575 -0.001 -0.0825"/>
    <parent link="fl_link4"/>
    <child link="fl_link5"/>
    <axis xyz="0 0 1"/>
    <limit effort="100" lower="-10" upper="10" velocity="1000"/>
  </joint>
  <link name="fl_link6">
    <inertial>
      <origin rpy="0 0 0" xyz="0.0471798400661976 0.000102970421835668 -0.000138510949393961"/>
      <mass value="0.462244960775882"/>
      <inertia ixx="0.00068" ixy="0.00000" ixz="0.00000" iyy="0.00036" iyz="-0.00001" izz="0.00091"/>
    </inertial>
    <visual>
      <origin rpy="0 0 0" xyz="0 0 0"/>
      <geometry>
        <mesh filename="package://arx5p2/meshes/link6.STL"/>
      </geometry>
      <material name="">
        <color rgba="0.898039215686275 0.917647058823529 0.929411764705882 1"/>
      </material>
    </visual>
    <collision>
      <origin rpy="0 0 0" xyz="0 0 0"/>
      <geometry>
        <mesh filename="package://arx5p2/meshes/link6.STL"/>
      </geometry>
    </collision>
  </link>
  <joint name="fl_joint6" type="revolute">
    <origin rpy="-3.1416 0 0" xyz="0.02845 0 0.0825"/>
    <parent link="fl_link5"/>
    <child link="fl_link6"/>
    <axis xyz="1 0 0"/>
    <limit effort="100" lower="-10" upper="10" velocity="1000"/>
  </joint>
  <link name="fl_link7">
    <inertial>
      <origin rpy="0 0 0" xyz="-0.000327642774520215 -0.00482005374028087 -0.00167540868720402"/>
      <mass value="0.0484016660227936"/>
      <inertia ixx="0.00001" ixy="0.00000" ixz="0.00000" iyy="0.00002" iyz="0.00000" izz="0.00002"/>
    </inertial>
    <visual>
      <origin rpy="0 0 0" xyz="0 0 0"/>
      <geometry>
        <mesh filename="package://arx5p2/meshes/link7.STL"/>
      </geometry>
      <material name="">
        <color rgba="0.898039215686275 0.917647058823529 0.929411764705882 1"/>
      </material>
    </visual>
    <collision>
      <origin rpy="0 0 0" xyz="0 0 0"/>
      <geometry>
        <mesh filename="package://arx5p2/meshes/link7.STL"/>
      </geometry>
    </collision>
  </link>
  <joint name="fl_joint7" type="prismatic">
    <origin rpy="0 0 0" xyz="0.073574 0.024629 0"/>
    <parent link="fl_link6"/>
    <child link="fl_link7"/>
    <axis xyz="0 1 0"/>
    <limit effort="100" lower="0" upper="0.04765" velocity="100"/>
  </joint>
  <link name="fl_link8">
    <inertial>
      <origin rpy="0 0 0" xyz="-0.000327643744208572 0.00482005363510456 0.000752972893839382"/>
      <mass value="0.0484016646136083"/>
      <inertia ixx="0.00001" ixy="0.00000" ixz="0.00000" iyy="0.00002" iyz="0.00000" izz="0.00002"/>
    </inertial>
    <visual>
      <origin rpy="0 0 0" xyz="0 0 0"/>
      <geometry>
        <mesh filename="package://arx5p2/meshes/link8.STL"/>
      </geometry>
      <material name="">
        <color rgba="0.898039215686275 0.917647058823529 0.929411764705882 1"/>
      </material>
    </visual>
    <collision>
      <origin rpy="0 0 0" xyz="0 0 0"/>
      <geometry>
        <mesh filename="package://arx5p2/meshes/link8.STL"/>
      </geometry>
    </collision>
  </link>
  <joint name="fl_joint8" type="prismatic">
    <origin rpy="0 0 0" xyz="0.073574 -0.024629 0"/>
    <parent link="fl_link6"/>
    <child link="fl_link8"/>
    <axis xyz="0 -1 0"/>
    <limit effort="100" lower="0" upper="0.04765" velocity="100"/>
  </joint>
  <!--***************************** front-right ****************************** -->
  <link name="fr_base_link">
    <inertial>
      <origin rpy="0 0 0" xyz="-2.9972E-05 3.056E-05 0.027301"/>
      <mass value="0.44038"/>
      <inertia ixx="0.00017" ixy="0.00000" ixz="0.00000" iyy="0.00018" iyz="0.00000" izz="0.00016"/>
    </inertial>
    <visual>
      <origin rpy="0 0 0" xyz="0 0 0"/>
      <geometry>
        <mesh filename="package://arx5_description/meshes/base_link.STL"/>
      </geometry>
      <material name="">
        <color rgba="0.75294 0.75294 0.75294 1"/>
      </material>
    </visual>
    <collision>
      <origin rpy="0 0 0" xyz="0 0 0"/>
      <geometry>
        <mesh filename="package://arx5_description/meshes/base_link.STL"/>
      </geometry>
    </collision>
  </link>
  <joint name="fr_base_joint" type="fixed">
    <origin rpy="0.0 0.0 0.0" xyz="0.233 -0.307 0.7775"/>
    <parent link="footprint"/>
    <child link="fr_base_link"/>
    <axis xyz="0.0 0.0 1.0"/>
  </joint>
  <link name="fr_link1">
    <inertial>
      <origin rpy="0 0 0" xyz="0.00609525411893452 -0.00429681977500749 0.0179590247477389"/>
      <mass value="0.0608351104988555"/>
      <inertia ixx="0.00008" ixy="0.00000" ixz="0.00001" iyy="0.00003" iyz="0.00000" izz="0.00007"/>
    </inertial>
    <visual>
      <origin rpy="0 0 0" xyz="0 0 0"/>
      <geometry>
        <mesh filename="package://arx5_description/meshes/link1.STL"/>
      </geometry>
      <material name="">
        <color rgba="0.752941176470588 0.752941176470588 0.752941176470588 1"/>
      </material>
    </visual>
    <collision>
      <origin rpy="0 0 0" xyz="0 0 0"/>
      <geometry>
        <mesh filename="package://arx5_description/meshes/link1.STL"/>
      </geometry>
    </collision>
  </link>
  <joint name="fr_joint1" type="revolute">
    <origin rpy="0 0 0" xyz="0 0 0.0603"/>
    <parent link="fr_base_link"/>
    <child link="fr_link1"/>
    <axis xyz="0 0 1"/>
    <limit effort="100" lower="-10" upper="10" velocity="1000"/>
  </joint>
  <link name="fr_link2">
    <inertial>
      <origin rpy="0 0 0" xyz="-0.132382037190567 0.00220380675553821 0.000111790164679923"/>
      <mass value="1.0733279014126"/>
      <inertia ixx="0.00050" ixy="0.00000" ixz="-0.00004" iyy="0.01596" iyz="0.00000" izz="0.01602"/>
    </inertial>
    <visual>
      <origin rpy="0 0 0" xyz="0 0 0"/>
      <geometry>
        <mesh filename="package://arx5_description/meshes/link2.STL"/>
      </geometry>
      <material name="">
        <color rgba="0.752941176470588 0.752941176470588 0.752941176470588 1"/>
      </material>
    </visual>
    <collision>
      <origin rpy="0 0 0" xyz="0 0 0"/>
      <geometry>
        <mesh filename="package://arx5_description/meshes/link2.STL"/>
      </geometry>
    </collision>
  </link>
  <joint name="fr_joint2" type="revolute">
    <origin rpy="0 0 0" xyz="0.02 0 0.0402"/>
    <parent link="fr_link1"/>
    <child link="fr_link2"/>
    <axis xyz="0 1 0"/>
    <limit effort="100" lower="-10" upper="10" velocity="1000"/>
  </joint>
  <link name="fr_link3">
    <inertial>
      <origin rpy="0 0 0" xyz="0.187203287369961 -0.000305676361444925 -0.0514832866415513"/>
      <mass value="0.499404738025019"/>
      <inertia ixx="0.00033" ixy="-0.00006" ixz="-0.00039" iyy="0.00387" iyz="0.00001" izz="0.00383"/>
    </inertial>
    <visual>
      <origin rpy="0 0 0" xyz="0 0 0"/>
      <geometry>
        <mesh filename="package://arx5_description/meshes/link3.STL"/>
      </geometry>
      <material name="">
        <color rgba="0.752941176470588 0.752941176470588 0.752941176470588 1"/>
      </material>
    </visual>
    <collision>
      <origin rpy="0 0 0" xyz="0 0 0"/>
      <geometry>
        <mesh filename="package://arx5_description/meshes/link3.STL"/>
      </geometry>
    </collision>
  </link>
  <joint name="fr_joint3" type="revolute">
    <origin rpy="-3.1416 0 0" xyz="-0.264 0 0"/>
    <parent link="fr_link2"/>
    <child link="fr_link3"/>
    <axis xyz="0 1 0"/>
    <limit effort="100" lower="-10" upper="10" velocity="1000"/>
  </joint>
  <link name="fr_link4">
    <inertial>
      <origin rpy="0 0 0" xyz="0.0388884702662706 0.00295168681334743 -0.0353282735009622"/>
      <mass value="0.0809712553169999"/>
      <inertia ixx="0.00013" ixy="-0.00001" ixz="-0.00006" iyy="0.00016" iyz="0.00001" izz="0.00010"/>
    </inertial>
    <visual>
      <origin rpy="0 0 0" xyz="0 0 0"/>
      <geometry>
        <mesh filename="package://arx5_description/meshes/link4.STL"/>
      </geometry>
      <material name="">
        <color rgba="0.898039215686275 0.917647058823529 0.929411764705882 1"/>
      </material>
    </visual>
    <collision>
      <origin rpy="0 0 0" xyz="0 0 0"/>
      <geometry>
        <mesh filename="package://arx5_description/meshes/link4.STL"/>
      </geometry>
    </collision>
  </link>
  <joint name="fr_joint4" type="revolute">
    <origin rpy="0 0 0" xyz="0.245 0 -0.056"/>
    <parent link="fr_link3"/>
    <child link="fr_link4"/>
    <axis xyz="0 1 0"/>
    <limit effort="100" lower="-10" upper="10" velocity="1000"/>
  </joint>
  <link name="fr_link5">
    <inertial>
      <origin rpy="0 0 0" xyz="0.00289956909960302 3.15826689885766E-05 0.0526188859211408"/>
      <mass value="0.602357399313257"/>
      <inertia ixx="0.00072" ixy="0.00000" ixz="0.00005" iyy="0.00069" iyz="0.00000" izz="0.00021"/>
    </inertial>
    <visual>
      <origin rpy="0 0 0" xyz="0 0 0"/>
      <geometry>
        <mesh filename="package://arx5_description/meshes/link5.STL"/>
      </geometry>
      <material name="">
        <color rgba="0.752941176470588 0.752941176470588 0.752941176470588 1"/>
      </material>
    </visual>
    <collision>
      <origin rpy="0 0 0" xyz="0 0 0"/>
      <geometry>
        <mesh filename="package://arx5_description/meshes/link5.STL"/>
      </geometry>
    </collision>
  </link>
  <joint name="fr_joint5" type="revolute">
    <origin rpy="0 0 0" xyz="0.06575 -0.001 -0.0825"/>
    <parent link="fr_link4"/>
    <child link="fr_link5"/>
    <axis xyz="0 0 1"/>
    <limit effort="100" lower="-10" upper="10" velocity="1000"/>
  </joint>
  <link name="fr_link6">
    <inertial>
      <origin rpy="0 0 0" xyz="0.0471798400661976 0.000102970421835668 -0.000138510949393961"/>
      <mass value="0.462244960775882"/>
      <inertia ixx="0.00068" ixy="0.00000" ixz="0.00000" iyy="0.00036" iyz="-0.00001" izz="0.00091"/>
    </inertial>
    <visual>
      <origin rpy="0 0 0" xyz="0 0 0"/>
      <geometry>
        <mesh filename="package://arx5p2/meshes/link6.STL"/>
      </geometry>
      <material name="">
        <color rgba="0.898039215686275 0.917647058823529 0.929411764705882 1"/>
      </material>
    </visual>
    <collision>
      <origin rpy="0 0 0" xyz="0 0 0"/>
      <geometry>
        <mesh filename="package://arx5p2/meshes/link6.STL"/>
      </geometry>
    </collision>
  </link>
  <joint name="fr_joint6" type="revolute">
    <origin rpy="-3.1416 0 0" xyz="0.02845 0 0.0825"/>
    <parent link="fr_link5"/>
    <child link="fr_link6"/>
    <axis xyz="1 0 0"/>
    <limit effort="100" lower="-10" upper="10" velocity="1000"/>
  </joint>
  <link name="fr_link7">
    <inertial>
      <origin rpy="0 0 0" xyz="-0.000327642774520215 -0.00482005374028087 -0.00167540868720402"/>
      <mass value="0.0484016660227936"/>
      <inertia ixx="0.00001" ixy="0.00000" ixz="0.00000" iyy="0.00002" iyz="0.00000" izz="0.00002"/>
    </inertial>
    <visual>
      <origin rpy="0 0 0" xyz="0 0 0"/>
      <geometry>
        <mesh filename="package://arx5p2/meshes/link7.STL"/>
      </geometry>
      <material name="">
        <color rgba="0.898039215686275 0.917647058823529 0.929411764705882 1"/>
      </material>
    </visual>
    <collision>
      <origin rpy="0 0 0" xyz="0 0 0"/>
      <geometry>
        <mesh filename="package://arx5p2/meshes/link7.STL"/>
      </geometry>
    </collision>
  </link>
  <joint name="fr_joint7" type="prismatic">
    <origin rpy="0 0 0" xyz="0.073574 0.024629 0"/>
    <parent link="fr_link6"/>
    <child link="fr_link7"/>
    <axis xyz="0 1 0"/>
    <limit effort="100" lower="0" upper="0.04765" velocity="100"/>
  </joint>
  <link name="fr_link8">
    <inertial>
      <origin rpy="0 0 0" xyz="-0.000327643744208572 0.00482005363510456 0.000752972893839382"/>
      <mass value="0.0484016646136083"/>
      <inertia ixx="0.00001" ixy="0.00000" ixz="0.00000" iyy="0.00002" iyz="0.00000" izz="0.00002"/>
    </inertial>
    <visual>
      <origin rpy="0 0 0" xyz="0 0 0"/>
      <geometry>
        <mesh filename="package://arx5p2/meshes/link8.STL"/>
      </geometry>
      <material name="">
        <color rgba="0.898039215686275 0.917647058823529 0.929411764705882 1"/>
      </material>
    </visual>
    <collision>
      <origin rpy="0 0 0" xyz="0 0 0"/>
      <geometry>
        <mesh filename="package://arx5p2/meshes/link8.STL"/>
      </geometry>
    </collision>
  </link>
  <joint name="fr_joint8" type="prismatic">
    <origin rpy="0 0 0" xyz="0.073574 -0.024629 0"/>
    <parent link="fr_link6"/>
    <child link="fr_link8"/>
    <axis xyz="0 -1 0"/>
    <limit effort="100" lower="0" upper="0.04765" velocity="100"/>
  </joint>
  <!--***************************** left-rear ****************************** -->
  <link name="lr_base_link">
    <inertial>
      <origin rpy="0 0 0" xyz="-2.9972E-05 3.056E-05 0.027301"/>
      <mass value="0.44038"/>
      <inertia ixx="0.00017" ixy="0.00000" ixz="0.00000" iyy="0.00018" iyz="0.00000" izz="0.00016"/>
    </inertial>
    <visual>
      <origin rpy="0 0 0" xyz="0 0 0"/>
      <geometry>
        <mesh filename="package://arx5_description/meshes/base_link.STL"/>
      </geometry>
      <material name="">
        <color rgba="0.75294 0.75294 0.75294 1"/>
      </material>
    </visual>
    <collision>
      <origin rpy="0 0 0" xyz="0 0 0"/>
      <geometry>
        <mesh filename="package://arx5_description/meshes/base_link.STL"/>
      </geometry>
    </collision>
  </link>
  <joint name="lr_base_joint" type="fixed">
    <origin rpy="0.0 0.0 0.0" xyz="-0.309 0.307 0.903"/>
    <parent link="footprint"/>
    <child link="lr_base_link"/>
    <axis xyz="0.0 0.0 1.0"/>
  </joint>
  <link name="lr_link1">
    <inertial>
      <origin rpy="0 0 0" xyz="0.00609525411893452 -0.00429681977500749 0.0179590247477389"/>
      <mass value="0.0608351104988555"/>
      <inertia ixx="0.00008" ixy="0.00000" ixz="0.00001" iyy="0.00003" iyz="0.00000" izz="0.00007"/>
    </inertial>
    <visual>
      <origin rpy="0 0 0" xyz="0 0 0"/>
      <geometry>
        <mesh filename="package://arx5_description/meshes/link1.STL"/>
      </geometry>
      <material name="">
        <color rgba="0.752941176470588 0.752941176470588 0.752941176470588 1"/>
      </material>
    </visual>
    <collision>
      <origin rpy="0 0 0" xyz="0 0 0"/>
      <geometry>
        <mesh filename="package://arx5_description/meshes/link1.STL"/>
      </geometry>
    </collision>
  </link>
  <joint name="lr_joint1" type="revolute">
    <origin rpy="0 0 0" xyz="0 0 0.0603"/>
    <parent link="lr_base_link"/>
    <child link="lr_link1"/>
    <axis xyz="0 0 1"/>
    <limit effort="100" lower="-10" upper="10" velocity="1000"/>
  </joint>
  <link name="lr_link2">
    <inertial>
      <origin rpy="0 0 0" xyz="-0.132382037190567 0.00220380675553821 0.000111790164679923"/>
      <mass value="1.0733279014126"/>
      <inertia ixx="0.00050" ixy="0.00000" ixz="-0.00004" iyy="0.01596" iyz="0.00000" izz="0.01602"/>
    </inertial>
    <visual>
      <origin rpy="0 0 0" xyz="0 0 0"/>
      <geometry>
        <mesh filename="package://arx5_description/meshes/link2.STL"/>
      </geometry>
      <material name="">
        <color rgba="0.752941176470588 0.752941176470588 0.752941176470588 1"/>
      </material>
    </visual>
    <collision>
      <origin rpy="0 0 0" xyz="0 0 0"/>
      <geometry>
        <mesh filename="package://arx5_description/meshes/link2.STL"/>
      </geometry>
    </collision>
  </link>
  <joint name="lr_joint2" type="revolute">
    <origin rpy="0 0 0" xyz="0.02 0 0.0402"/>
    <parent link="lr_link1"/>
    <child link="lr_link2"/>
    <axis xyz="0 1 0"/>
    <dynamics damping="0.0" friction="100.0"/>
    <limit effort="100" lower="-10" upper="10" velocity="1000"/>
  </joint>
  <link name="lr_link3">
    <inertial>
      <origin rpy="0 0 0" xyz="0.187203287369961 -0.000305676361444925 -0.0514832866415513"/>
      <mass value="0.499404738025019"/>
      <inertia ixx="0.00033" ixy="-0.00006" ixz="-0.00039" iyy="0.00387" iyz="0.00001" izz="0.00383"/>
    </inertial>
    <visual>
      <origin rpy="0 0 0" xyz="0 0 0"/>
      <geometry>
        <mesh filename="package://arx5_description/meshes/link3.STL"/>
      </geometry>
      <material name="">
        <color rgba="0.752941176470588 0.752941176470588 0.752941176470588 1"/>
      </material>
    </visual>
    <collision>
      <origin rpy="0 0 0" xyz="0 0 0"/>
      <geometry>
        <mesh filename="package://arx5_description/meshes/link3.STL"/>
      </geometry>
    </collision>
  </link>
  <joint name="lr_joint3" type="revolute">
    <origin rpy="-3.1416 0 0" xyz="-0.264 0 0"/>
    <parent link="lr_link2"/>
    <child link="lr_link3"/>
    <axis xyz="0 1 0"/>
    <dynamics damping="0.0" friction="100.0"/>
    <limit effort="100" lower="-10" upper="10" velocity="1000"/>
  </joint>
  <link name="lr_link4">
    <inertial>
      <origin rpy="0 0 0" xyz="0.0388884702662706 0.00295168681334743 -0.0353282735009622"/>
      <mass value="0.0809712553169999"/>
      <inertia ixx="0.00013" ixy="-0.00001" ixz="-0.00006" iyy="0.00016" iyz="0.00001" izz="0.00010"/>
    </inertial>
    <visual>
      <origin rpy="0 0 0" xyz="0 0 0"/>
      <geometry>
        <mesh filename="package://arx5_description/meshes/link4.STL"/>
      </geometry>
      <material name="">
        <color rgba="0.898039215686275 0.917647058823529 0.929411764705882 1"/>
      </material>
    </visual>
    <collision>
      <origin rpy="0 0 0" xyz="0 0 0"/>
      <geometry>
        <mesh filename="package://arx5_description/meshes/link4.STL"/>
      </geometry>
    </collision>
  </link>
  <joint name="lr_joint4" type="revolute">
    <origin rpy="0 0 0" xyz="0.245 0 -0.056"/>
    <parent link="lr_link3"/>
    <child link="lr_link4"/>
    <axis xyz="0 1 0"/>
    <limit effort="100" lower="-10" upper="10" velocity="1000"/>
  </joint>
  <link name="lr_link5">
    <inertial>
      <origin rpy="0 0 0" xyz="0.00289956909960302 3.15826689885766E-05 0.0526188859211408"/>
      <mass value="0.602357399313257"/>
      <inertia ixx="0.00072" ixy="0.00000" ixz="0.00005" iyy="0.00069" iyz="0.00000" izz="0.00021"/>
    </inertial>
    <visual>
      <origin rpy="0 0 0" xyz="0 0 0"/>
      <geometry>
        <mesh filename="package://arx5_description/meshes/link5.STL"/>
      </geometry>
      <material name="">
        <color rgba="0.752941176470588 0.752941176470588 0.752941176470588 1"/>
      </material>
    </visual>
    <collision>
      <origin rpy="0 0 0" xyz="0 0 0"/>
      <geometry>
        <mesh filename="package://arx5_description/meshes/link5.STL"/>
      </geometry>
    </collision>
  </link>
  <joint name="lr_joint5" type="revolute">
    <origin rpy="0 0 0" xyz="0.06575 -0.001 -0.0825"/>
    <parent link="lr_link4"/>
    <child link="lr_link5"/>
    <axis xyz="0 0 1"/>
    <limit effort="100" lower="-10" upper="10" velocity="1000"/>
  </joint>
  <link name="lr_link6">
    <inertial>
      <origin rpy="0 0 0" xyz="0.0471798400661976 0.000102970421835668 -0.000138510949393961"/>
      <mass value="0.462244960775882"/>
      <inertia ixx="0.00068" ixy="0.00000" ixz="0.00000" iyy="0.00036" iyz="-0.00001" izz="0.00091"/>
    </inertial>
    <visual>
      <origin rpy="0 0 0" xyz="0 0 0"/>
      <geometry>
        <mesh filename="package://arx5p2/meshes/link6.STL"/>
      </geometry>
      <material name="">
        <color rgba="0.898039215686275 0.917647058823529 0.929411764705882 1"/>
      </material>
    </visual>
    <collision>
      <origin rpy="0 0 0" xyz="0 0 0"/>
      <geometry>
        <mesh filename="package://arx5p2/meshes/link6.STL"/>
      </geometry>
    </collision>
  </link>
  <joint name="lr_joint6" type="revolute">
    <origin rpy="-3.1416 0 0" xyz="0.02845 0 0.0825"/>
    <parent link="lr_link5"/>
    <child link="lr_link6"/>
    <axis xyz="1 0 0"/>
    <limit effort="100" lower="-10" upper="10" velocity="1000"/>
  </joint>
  <link name="lr_link7">
    <inertial>
      <origin rpy="0 0 0" xyz="-0.000327642774520215 -0.00482005374028087 -0.00167540868720402"/>
      <mass value="0.0484016660227936"/>
      <inertia ixx="0.00001" ixy="0.00000" ixz="0.00000" iyy="0.00002" iyz="0.00000" izz="0.00002"/>
    </inertial>
    <visual>
      <origin rpy="0 0 0" xyz="0 0 0"/>
      <geometry>
        <mesh filename="package://arx5p2/meshes/link7.STL"/>
      </geometry>
      <material name="">
        <color rgba="0.898039215686275 0.917647058823529 0.929411764705882 1"/>
      </material>
    </visual>
    <collision>
      <origin rpy="0 0 0" xyz="0 0 0"/>
      <geometry>
        <mesh filename="package://arx5p2/meshes/link7.STL"/>
      </geometry>
    </collision>
  </link>
  <joint name="lr_joint7" type="prismatic">
    <origin rpy="0 0 0" xyz="0.073574 0.024629 0"/>
    <parent link="lr_link6"/>
    <child link="lr_link7"/>
    <axis xyz="0 1 0"/>
    <limit effort="100" lower="0" upper="0.04765" velocity="100"/>
  </joint>
  <link name="lr_link8">
    <inertial>
      <origin rpy="0 0 0" xyz="-0.000327643744208572 0.00482005363510456 0.000752972893839382"/>
      <mass value="0.0484016646136083"/>
      <inertia ixx="0.00001" ixy="0.00000" ixz="0.00000" iyy="0.00002" iyz="0.00000" izz="0.00002"/>
    </inertial>
    <visual>
      <origin rpy="0 0 0" xyz="0 0 0"/>
      <geometry>
        <mesh filename="package://arx5p2/meshes/link8.STL"/>
      </geometry>
      <material name="">
        <color rgba="0.898039215686275 0.917647058823529 0.929411764705882 1"/>
      </material>
    </visual>
    <collision>
      <origin rpy="0 0 0" xyz="0 0 0"/>
      <geometry>
        <mesh filename="package://arx5p2/meshes/link8.STL"/>
      </geometry>
    </collision>
  </link>
  <joint name="lr_joint8" type="prismatic">
    <origin rpy="0 0 0" xyz="0.073574 -0.024629 0"/>
    <parent link="lr_link6"/>
    <child link="lr_link8"/>
    <axis xyz="0 -1 0"/>
    <limit effort="100" lower="0" upper="0.04765" velocity="100"/>
  </joint>
  <!--***************************** right-rear ****************************** -->
  <link name="rr_base_link">
    <inertial>
      <origin rpy="0 0 0" xyz="-2.9972E-05 3.056E-05 0.027301"/>
      <mass value="0.44038"/>
      <inertia ixx="0.00017" ixy="0.00000" ixz="0.00000" iyy="0.00018" iyz="0.00000" izz="0.00016"/>
    </inertial>
    <visual>
      <origin rpy="0 0 0" xyz="0 0 0"/>
      <geometry>
        <mesh filename="package://arx5_description/meshes/base_link.STL"/>
      </geometry>
      <material name="">
        <color rgba="0.75294 0.75294 0.75294 1"/>
      </material>
    </visual>
    <collision>
      <origin rpy="0 0 0" xyz="0 0 0"/>
      <geometry>
        <mesh filename="package://arx5_description/meshes/base_link.STL"/>
      </geometry>
    </collision>
  </link>
  <joint name="rr_base_joint" type="fixed">
    <origin rpy="0.0 0.0 0.0" xyz="-0.309 -0.307 0.903"/>
    <parent link="footprint"/>
    <child link="rr_base_link"/>
    <axis xyz="0.0 0.0 1.0"/>
  </joint>
  <link name="rr_link1">
    <inertial>
      <origin rpy="0 0 0" xyz="0.00609525411893452 -0.00429681977500749 0.0179590247477389"/>
      <mass value="0.0608351104988555"/>
      <inertia ixx="0.00008" ixy="0.00000" ixz="0.00001" iyy="0.00003" iyz="0.00000" izz="0.00007"/>
    </inertial>
    <visual>
      <origin rpy="0 0 0" xyz="0 0 0"/>
      <geometry>
        <mesh filename="package://arx5_description/meshes/link1.STL"/>
      </geometry>
      <material name="">
        <color rgba="0.752941176470588 0.752941176470588 0.752941176470588 1"/>
      </material>
    </visual>
    <collision>
      <origin rpy="0 0 0" xyz="0 0 0"/>
      <geometry>
        <mesh filename="package://arx5_description/meshes/link1.STL"/>
      </geometry>
    </collision>
  </link>
  <joint name="rr_joint1" type="revolute">
    <origin rpy="0 0 0" xyz="0 0 0.0603"/>
    <parent link="rr_base_link"/>
    <child link="rr_link1"/>
    <axis xyz="0 0 1"/>
    <limit effort="100" lower="-10" upper="10" velocity="1000"/>
  </joint>
  <link name="rr_link2">
    <inertial>
      <origin rpy="0 0 0" xyz="-0.132382037190567 0.00220380675553821 0.000111790164679923"/>
      <mass value="1.0733279014126"/>
      <inertia ixx="0.00050" ixy="0.00000" ixz="-0.00004" iyy="0.01596" iyz="0.00000" izz="0.01602"/>
    </inertial>
    <visual>
      <origin rpy="0 0 0" xyz="0 0 0"/>
      <geometry>
        <mesh filename="package://arx5_description/meshes/link2.STL"/>
      </geometry>
      <material name="">
        <color rgba="0.752941176470588 0.752941176470588 0.752941176470588 1"/>
      </material>
    </visual>
    <collision>
      <origin rpy="0 0 0" xyz="0 0 0"/>
      <geometry>
        <mesh filename="package://arx5_description/meshes/link2.STL"/>
      </geometry>
    </collision>
  </link>
  <joint name="rr_joint2" type="revolute">
    <origin rpy="0 0 0" xyz="0.02 0 0.0402"/>
    <parent link="rr_link1"/>
    <child link="rr_link2"/>
    <axis xyz="0 1 0"/>
    <limit effort="100" lower="-10" upper="10" velocity="1000"/>
  </joint>
  <link name="rr_link3">
    <inertial>
      <origin rpy="0 0 0" xyz="0.187203287369961 -0.000305676361444925 -0.0514832866415513"/>
      <mass value="0.499404738025019"/>
      <inertia ixx="0.00033" ixy="-0.00006" ixz="-0.00039" iyy="0.00387" iyz="0.00001" izz="0.00383"/>
    </inertial>
    <visual>
      <origin rpy="0 0 0" xyz="0 0 0"/>
      <geometry>
        <mesh filename="package://arx5_description/meshes/link3.STL"/>
      </geometry>
      <material name="">
        <color rgba="0.752941176470588 0.752941176470588 0.752941176470588 1"/>
      </material>
    </visual>
    <collision>
      <origin rpy="0 0 0" xyz="0 0 0"/>
      <geometry>
        <mesh filename="package://arx5_description/meshes/link3.STL"/>
      </geometry>
    </collision>
  </link>
  <joint name="rr_joint3" type="revolute">
    <origin rpy="-3.1416 0 0" xyz="-0.264 0 0"/>
    <parent link="rr_link2"/>
    <child link="rr_link3"/>
    <axis xyz="0 1 0"/>
    <limit effort="100" lower="-10" upper="10" velocity="1000"/>
  </joint>
  <link name="rr_link4">
    <inertial>
      <origin rpy="0 0 0" xyz="0.0388884702662706 0.00295168681334743 -0.0353282735009622"/>
      <mass value="0.0809712553169999"/>
      <inertia ixx="0.00013" ixy="-0.00001" ixz="-0.00006" iyy="0.00016" iyz="0.00001" izz="0.00010"/>
    </inertial>
    <visual>
      <origin rpy="0 0 0" xyz="0 0 0"/>
      <geometry>
        <mesh filename="package://arx5_description/meshes/link4.STL"/>
      </geometry>
      <material name="">
        <color rgba="0.898039215686275 0.917647058823529 0.929411764705882 1"/>
      </material>
    </visual>
    <collision>
      <origin rpy="0 0 0" xyz="0 0 0"/>
      <geometry>
        <mesh filename="package://arx5_description/meshes/link4.STL"/>
      </geometry>
    </collision>
  </link>
  <joint name="rr_joint4" type="revolute">
    <origin rpy="0 0 0" xyz="0.245 0 -0.056"/>
    <parent link="rr_link3"/>
    <child link="rr_link4"/>
    <axis xyz="0 1 0"/>
    <limit effort="100" lower="-10" upper="10" velocity="1000"/>
  </joint>
  <link name="rr_link5">
    <inertial>
      <origin rpy="0 0 0" xyz="0.00289956909960302 3.15826689885766E-05 0.0526188859211408"/>
      <mass value="0.602357399313257"/>
      <inertia ixx="0.00072" ixy="0.00000" ixz="0.00005" iyy="0.00069" iyz="0.00000" izz="0.00021"/>
    </inertial>
    <visual>
      <origin rpy="0 0 0" xyz="0 0 0"/>
      <geometry>
        <mesh filename="package://arx5_description/meshes/link5.STL"/>
      </geometry>
      <material name="">
        <color rgba="0.752941176470588 0.752941176470588 0.752941176470588 1"/>
      </material>
    </visual>
    <collision>
      <origin rpy="0 0 0" xyz="0 0 0"/>
      <geometry>
        <mesh filename="package://arx5_description/meshes/link5.STL"/>
      </geometry>
    </collision>
  </link>
  <joint name="rr_joint5" type="revolute">
    <origin rpy="0 0 0" xyz="0.06575 -0.001 -0.0825"/>
    <parent link="rr_link4"/>
    <child link="rr_link5"/>
    <axis xyz="0 0 1"/>
    <limit effort="100" lower="-10" upper="10" velocity="1000"/>
  </joint>
  <link name="rr_link6">
    <inertial>
      <origin rpy="0 0 0" xyz="0.0471798400661976 0.000102970421835668 -0.000138510949393961"/>
      <mass value="0.462244960775882"/>
      <inertia ixx="0.00068" ixy="0.00000" ixz="0.00000" iyy="0.00036" iyz="-0.00001" izz="0.00091"/>
    </inertial>
    <visual>
      <origin rpy="0 0 0" xyz="0 0 0"/>
      <geometry>
        <mesh filename="package://arx5p2/meshes/link6.STL"/>
      </geometry>
      <material name="">
        <color rgba="0.898039215686275 0.917647058823529 0.929411764705882 1"/>
      </material>
    </visual>
    <collision>
      <origin rpy="0 0 0" xyz="0 0 0"/>
      <geometry>
        <mesh filename="package://arx5p2/meshes/link6.STL"/>
      </geometry>
    </collision>
  </link>
  <joint name="rr_joint6" type="revolute">
    <origin rpy="-3.1416 0 0" xyz="0.02845 0 0.0825"/>
    <parent link="rr_link5"/>
    <child link="rr_link6"/>
    <axis xyz="1 0 0"/>
    <limit effort="100" lower="-10" upper="10" velocity="1000"/>
  </joint>
  <link name="rr_link7">
    <inertial>
      <origin rpy="0 0 0" xyz="-0.000327642774520215 -0.00482005374028087 -0.00167540868720402"/>
      <mass value="0.0484016660227936"/>
      <inertia ixx="0.00001" ixy="0.00000" ixz="0.00000" iyy="0.00002" iyz="0.00000" izz="0.00002"/>
    </inertial>
    <visual>
      <origin rpy="0 0 0" xyz="0 0 0"/>
      <geometry>
        <mesh filename="package://arx5p2/meshes/link7.STL"/>
      </geometry>
      <material name="">
        <color rgba="0.898039215686275 0.917647058823529 0.929411764705882 1"/>
      </material>
    </visual>
    <collision>
      <origin rpy="0 0 0" xyz="0 0 0"/>
      <geometry>
        <mesh filename="package://arx5p2/meshes/link7.STL"/>
      </geometry>
    </collision>
  </link>
  <joint name="rr_joint7" type="prismatic">
    <origin rpy="0 0 0" xyz="0.073574 0.024629 0"/>
    <parent link="rr_link6"/>
    <child link="rr_link7"/>
    <axis xyz="0 1 0"/>
    <limit effort="100" lower="0" upper="0.04765" velocity="100"/>
  </joint>
  <link name="rr_link8">
    <inertial>
      <origin rpy="0 0 0" xyz="-0.000327643744208572 0.00482005363510456 0.000752972893839382"/>
      <mass value="0.0484016646136083"/>
      <inertia ixx="0.00001" ixy="0.00000" ixz="0.00000" iyy="0.00002" iyz="0.00000" izz="0.00002"/>
    </inertial>
    <visual>
      <origin rpy="0 0 0" xyz="0 0 0"/>
      <geometry>
        <mesh filename="package://arx5p2/meshes/link8.STL"/>
      </geometry>
      <material name="">
        <color rgba="0.898039215686275 0.917647058823529 0.929411764705882 1"/>
      </material>
    </visual>
    <collision>
      <origin rpy="0 0 0" xyz="0 0 0"/>
      <geometry>
        <mesh filename="package://arx5p2/meshes/link8.STL"/>
      </geometry>
    </collision>
  </link>
  <joint name="rr_joint8" type="prismatic">
    <origin rpy="0 0 0" xyz="0.073574 -0.024629 0"/>
    <parent link="rr_link6"/>
    <child link="rr_link8"/>
    <axis xyz="0 -1 0"/>
    <limit effort="100" lower="0" upper="0.04765" velocity="100"/>
  </joint>
  <transmission name="trans_fl_joint1">
    <type>transmission_interface/SimpleTransmission</type>
    <joint name="fl_joint1">
      <hardwareInterface>hardware_interface/PositionJointInterface</hardwareInterface>
    </joint>
    <actuator name="fl_joint1_motor">
      <hardwareInterface>hardware_interface/PositionJointInterface</hardwareInterface>
      <mechanicalReduction>1</mechanicalReduction>
    </actuator>
  </transmission>
  <transmission name="trans_fl_joint2">
    <type>transmission_interface/SimpleTransmission</type>
    <joint name="fl_joint2">
      <hardwareInterface>hardware_interface/PositionJointInterface</hardwareInterface>
    </joint>
    <actuator name="fl_joint2_motor">
      <hardwareInterface>hardware_interface/PositionJointInterface</hardwareInterface>
      <mechanicalReduction>1</mechanicalReduction>
    </actuator>
  </transmission>
  <transmission name="trans_fl_joint3">
    <type>transmission_interface/SimpleTransmission</type>
    <joint name="fl_joint3">
      <hardwareInterface>hardware_interface/PositionJointInterface</hardwareInterface>
    </joint>
    <actuator name="fl_joint3_motor">
      <hardwareInterface>hardware_interface/PositionJointInterface</hardwareInterface>
      <mechanicalReduction>1</mechanicalReduction>
    </actuator>
  </transmission>
  <transmission name="trans_fl_joint4">
    <type>transmission_interface/SimpleTransmission</type>
    <joint name="fl_joint4">
      <hardwareInterface>hardware_interface/PositionJointInterface</hardwareInterface>
    </joint>
    <actuator name="fl_joint4_motor">
      <hardwareInterface>hardware_interface/PositionJointInterface</hardwareInterface>
      <mechanicalReduction>1</mechanicalReduction>
    </actuator>
  </transmission>
  <transmission name="trans_fl_joint5">
    <type>transmission_interface/SimpleTransmission</type>
    <joint name="fl_joint5">
      <hardwareInterface>hardware_interface/PositionJointInterface</hardwareInterface>
    </joint>
    <actuator name="fl_joint5_motor">
      <hardwareInterface>hardware_interface/PositionJointInterface</hardwareInterface>
      <mechanicalReduction>1</mechanicalReduction>
    </actuator>
  </transmission>
  <transmission name="trans_fl_joint6">
    <type>transmission_interface/SimpleTransmission</type>
    <joint name="fl_joint6">
      <hardwareInterface>hardware_interface/PositionJointInterface</hardwareInterface>
    </joint>
    <actuator name="fl_joint6_motor">
      <hardwareInterface>hardware_interface/PositionJointInterface</hardwareInterface>
      <mechanicalReduction>1</mechanicalReduction>
    </actuator>
  </transmission>
  <transmission name="trans_fl_joint7">
    <type>transmission_interface/SimpleTransmission</type>
    <joint name="fl_joint7">
      <hardwareInterface>hardware_interface/PositionJointInterface</hardwareInterface>
    </joint>
    <actuator name="fl_joint7_motor">
      <hardwareInterface>hardware_interface/PositionJointInterface</hardwareInterface>
      <mechanicalReduction>1</mechanicalReduction>
    </actuator>
  </transmission>
  <transmission name="trans_fl_joint8">
    <type>transmission_interface/SimpleTransmission</type>
    <joint name="fl_joint8">
      <hardwareInterface>hardware_interface/PositionJointInterface</hardwareInterface>
    </joint>
    <actuator name="fl_joint8_motor">
      <hardwareInterface>hardware_interface/PositionJointInterface</hardwareInterface>
      <mechanicalReduction>1</mechanicalReduction>
    </actuator>
  </transmission>
  <transmission name="trans_fr_joint1">
    <type>transmission_interface/SimpleTransmission</type>
    <joint name="fr_joint1">
      <hardwareInterface>hardware_interface/PositionJointInterface</hardwareInterface>
    </joint>
    <actuator name="fr_joint1_motor">
      <hardwareInterface>hardware_interface/PositionJointInterface</hardwareInterface>
      <mechanicalReduction>1</mechanicalReduction>
    </actuator>
  </transmission>
  <transmission name="trans_fr_joint2">
    <type>transmission_interface/SimpleTransmission</type>
    <joint name="fr_joint2">
      <hardwareInterface>hardware_interface/PositionJointInterface</hardwareInterface>
    </joint>
    <actuator name="fr_joint2_motor">
      <hardwareInterface>hardware_interface/PositionJointInterface</hardwareInterface>
      <mechanicalReduction>1</mechanicalReduction>
    </actuator>
  </transmission>
  <transmission name="trans_fr_joint3">
    <type>transmission_interface/SimpleTransmission</type>
    <joint name="fr_joint3">
      <hardwareInterface>hardware_interface/PositionJointInterface</hardwareInterface>
    </joint>
    <actuator name="fr_joint3_motor">
      <hardwareInterface>hardware_interface/PositionJointInterface</hardwareInterface>
      <mechanicalReduction>1</mechanicalReduction>
    </actuator>
  </transmission>
  <transmission name="trans_fr_joint4">
    <type>transmission_interface/SimpleTransmission</type>
    <joint name="fr_joint4">
      <hardwareInterface>hardware_interface/PositionJointInterface</hardwareInterface>
    </joint>
    <actuator name="fr_joint4_motor">
      <hardwareInterface>hardware_interface/PositionJointInterface</hardwareInterface>
      <mechanicalReduction>1</mechanicalReduction>
    </actuator>
  </transmission>
  <transmission name="trans_fr_joint5">
    <type>transmission_interface/SimpleTransmission</type>
    <joint name="fr_joint5">
      <hardwareInterface>hardware_interface/PositionJointInterface</hardwareInterface>
    </joint>
    <actuator name="fr_joint5_motor">
      <hardwareInterface>hardware_interface/PositionJointInterface</hardwareInterface>
      <mechanicalReduction>1</mechanicalReduction>
    </actuator>
  </transmission>
  <transmission name="trans_fr_joint6">
    <type>transmission_interface/SimpleTransmission</type>
    <joint name="fr_joint6">
      <hardwareInterface>hardware_interface/PositionJointInterface</hardwareInterface>
    </joint>
    <actuator name="fr_joint6_motor">
      <hardwareInterface>hardware_interface/PositionJointInterface</hardwareInterface>
      <mechanicalReduction>1</mechanicalReduction>
    </actuator>
  </transmission>
  <transmission name="trans_fr_joint7">
    <type>transmission_interface/SimpleTransmission</type>
    <joint name="fr_joint7">
      <hardwareInterface>hardware_interface/PositionJointInterface</hardwareInterface>
    </joint>
    <actuator name="fr_joint7_motor">
      <hardwareInterface>hardware_interface/PositionJointInterface</hardwareInterface>
      <mechanicalReduction>1</mechanicalReduction>
    </actuator>
  </transmission>
  <transmission name="trans_fr_joint8">
    <type>transmission_interface/SimpleTransmission</type>
    <joint name="fr_joint8">
      <hardwareInterface>hardware_interface/PositionJointInterface</hardwareInterface>
    </joint>
    <actuator name="fr_joint8_motor">
      <hardwareInterface>hardware_interface/PositionJointInterface</hardwareInterface>
      <mechanicalReduction>1</mechanicalReduction>
    </actuator>
  </transmission>
  <transmission name="trans_lr_joint1">
    <type>transmission_interface/SimpleTransmission</type>
    <joint name="lr_joint1">
      <hardwareInterface>hardware_interface/PositionJointInterface</hardwareInterface>
    </joint>
    <actuator name="lr_joint1_motor">
      <hardwareInterface>hardware_interface/PositionJointInterface</hardwareInterface>
      <mechanicalReduction>1</mechanicalReduction>
    </actuator>
  </transmission>
  <transmission name="trans_lr_joint2">
    <type>transmission_interface/SimpleTransmission</type>
    <joint name="lr_joint2">
      <hardwareInterface>hardware_interface/PositionJointInterface</hardwareInterface>
    </joint>
    <actuator name="lr_joint2_motor">
      <hardwareInterface>hardware_interface/PositionJointInterface</hardwareInterface>
      <mechanicalReduction>1</mechanicalReduction>
    </actuator>
  </transmission>
  <transmission name="trans_lr_joint3">
    <type>transmission_interface/SimpleTransmission</type>
    <joint name="lr_joint3">
      <hardwareInterface>hardware_interface/PositionJointInterface</hardwareInterface>
    </joint>
    <actuator name="lr_joint3_motor">
      <hardwareInterface>hardware_interface/PositionJointInterface</hardwareInterface>
      <mechanicalReduction>1</mechanicalReduction>
    </actuator>
  </transmission>
  <transmission name="trans_lr_joint4">
    <type>transmission_interface/SimpleTransmission</type>
    <joint name="lr_joint4">
      <hardwareInterface>hardware_interface/PositionJointInterface</hardwareInterface>
    </joint>
    <actuator name="lr_joint4_motor">
      <hardwareInterface>hardware_interface/PositionJointInterface</hardwareInterface>
      <mechanicalReduction>1</mechanicalReduction>
    </actuator>
  </transmission>
  <transmission name="trans_lr_joint5">
    <type>transmission_interface/SimpleTransmission</type>
    <joint name="lr_joint5">
      <hardwareInterface>hardware_interface/PositionJointInterface</hardwareInterface>
    </joint>
    <actuator name="lr_joint5_motor">
      <hardwareInterface>hardware_interface/PositionJointInterface</hardwareInterface>
      <mechanicalReduction>1</mechanicalReduction>
    </actuator>
  </transmission>
  <transmission name="trans_lr_joint6">
    <type>transmission_interface/SimpleTransmission</type>
    <joint name="lr_joint6">
      <hardwareInterface>hardware_interface/PositionJointInterface</hardwareInterface>
    </joint>
    <actuator name="lr_joint6_motor">
      <hardwareInterface>hardware_interface/PositionJointInterface</hardwareInterface>
      <mechanicalReduction>1</mechanicalReduction>
    </actuator>
  </transmission>
  <transmission name="trans_lr_joint7">
    <type>transmission_interface/SimpleTransmission</type>
    <joint name="lr_joint7">
      <hardwareInterface>hardware_interface/PositionJointInterface</hardwareInterface>
    </joint>
    <actuator name="lr_joint7_motor">
      <hardwareInterface>hardware_interface/PositionJointInterface</hardwareInterface>
      <mechanicalReduction>1</mechanicalReduction>
    </actuator>
  </transmission>
  <transmission name="trans_lr_joint8">
    <type>transmission_interface/SimpleTransmission</type>
    <joint name="lr_joint8">
      <hardwareInterface>hardware_interface/PositionJointInterface</hardwareInterface>
    </joint>
    <actuator name="lr_joint8_motor">
      <hardwareInterface>hardware_interface/PositionJointInterface</hardwareInterface>
      <mechanicalReduction>1</mechanicalReduction>
    </actuator>
  </transmission>
  <transmission name="trans_rr_joint1">
    <type>transmission_interface/SimpleTransmission</type>
    <joint name="rr_joint1">
      <hardwareInterface>hardware_interface/PositionJointInterface</hardwareInterface>
    </joint>
    <actuator name="rr_joint1_motor">
      <hardwareInterface>hardware_interface/PositionJointInterface</hardwareInterface>
      <mechanicalReduction>1</mechanicalReduction>
    </actuator>
  </transmission>
  <transmission name="trans_rr_joint2">
    <type>transmission_interface/SimpleTransmission</type>
    <joint name="rr_joint2">
      <hardwareInterface>hardware_interface/PositionJointInterface</hardwareInterface>
    </joint>
    <actuator name="rr_joint2_motor">
      <hardwareInterface>hardware_interface/PositionJointInterface</hardwareInterface>
      <mechanicalReduction>1</mechanicalReduction>
    </actuator>
  </transmission>
  <transmission name="trans_rr_joint3">
    <type>transmission_interface/SimpleTransmission</type>
    <joint name="rr_joint3">
      <hardwareInterface>hardware_interface/PositionJointInterface</hardwareInterface>
    </joint>
    <actuator name="rr_joint3_motor">
      <hardwareInterface>hardware_interface/PositionJointInterface</hardwareInterface>
      <mechanicalReduction>1</mechanicalReduction>
    </actuator>
  </transmission>
  <transmission name="trans_rr_joint4">
    <type>transmission_interface/SimpleTransmission</type>
    <joint name="rr_joint4">
      <hardwareInterface>hardware_interface/PositionJointInterface</hardwareInterface>
    </joint>
    <actuator name="rr_joint4_motor">
      <hardwareInterface>hardware_interface/PositionJointInterface</hardwareInterface>
      <mechanicalReduction>1</mechanicalReduction>
    </actuator>
  </transmission>
  <transmission name="trans_rr_joint5">
    <type>transmission_interface/SimpleTransmission</type>
    <joint name="rr_joint5">
      <hardwareInterface>hardware_interface/PositionJointInterface</hardwareInterface>
    </joint>
    <actuator name="rr_joint5_motor">
      <hardwareInterface>hardware_interface/PositionJointInterface</hardwareInterface>
      <mechanicalReduction>1</mechanicalReduction>
    </actuator>
  </transmission>
  <transmission name="trans_rr_joint6">
    <type>transmission_interface/SimpleTransmission</type>
    <joint name="rr_joint6">
      <hardwareInterface>hardware_interface/PositionJointInterface</hardwareInterface>
    </joint>
    <actuator name="rr_joint6_motor">
      <hardwareInterface>hardware_interface/PositionJointInterface</hardwareInterface>
      <mechanicalReduction>1</mechanicalReduction>
    </actuator>
  </transmission>
  <transmission name="trans_rr_joint7">
    <type>transmission_interface/SimpleTransmission</type>
    <joint name="rr_joint7">
      <hardwareInterface>hardware_interface/PositionJointInterface</hardwareInterface>
    </joint>
    <actuator name="rr_joint7_motor">
      <hardwareInterface>hardware_interface/PositionJointInterface</hardwareInterface>
      <mechanicalReduction>1</mechanicalReduction>
    </actuator>
  </transmission>
  <transmission name="trans_rr_joint8">
    <type>transmission_interface/SimpleTransmission</type>
    <joint name="rr_joint8">
      <hardwareInterface>hardware_interface/PositionJointInterface</hardwareInterface>
    </joint>
    <actuator name="rr_joint8_motor">
      <hardwareInterface>hardware_interface/PositionJointInterface</hardwareInterface>
      <mechanicalReduction>1</mechanicalReduction>
    </actuator>
  </transmission>
  <!-- position controller -->
  <!-- <gazebo>
        <plugin name="base_controller" filename="libgazebo_ros_planar_move.so">
            <robotNamespace>/</robotNamespace>
            <commandTopic>cmd_vel</commandTopic>
            <odometryTopic>odom</odometryTopic>
            <odometryFrame>/odom</odometryFrame>
            <odometryRate>100.0</odometryRate>
            <robotBaseFrame>box</robotBaseFrame>
            <broadcastTF>false</broadcastTF>
        </plugin>
    </gazebo> -->
</robot>

