<mujoco model="arx5_description">
  <compiler angle="radian" meshdir="../meshes_mujoco/"/>

  <asset>
    <mesh name="tracer_base_link_no_wheel" file="tracer_base_link_no_wheel.stl"/>
    <mesh name="tracer_wheel" file="tracer_wheel.stl"/>
    <mesh name="castor_joint" file="castor_joint.stl"/>
    <mesh name="castor" file="castor.stl"/>
    <mesh name="livox_mid360" file="livox_mid360.stl" scale="0.001 0.001 0.001"/>
    <mesh name="realsense_d435_binary" file="realsense_d435_binary.stl"/>
    <mesh name="box1_Link" file="box1_Link.STL"/>
    <mesh name="box2_Link" file="box2_Link.STL"/>
    <mesh name="base_link" file="base_link.STL"/>
    <mesh name="link1" file="link1.STL"/>
    <mesh name="link2" file="link2.STL"/>
    <mesh name="link3" file="link3.STL"/>
    <mesh name="link4" file="link4.STL"/>
    <mesh name="link5" file="link5.STL"/>
    <mesh name="link6" file="link6.STL"/>
    <mesh name="link7" file="link7.STL"/>
    <mesh name="link8" file="link8.STL"/>
  </asset>

  <worldbody>
    <geom pos="0.1849 -0.01 0.8525" quat="0.5 0.5 0.5 0.5" type="mesh" contype="0" conaffinity="0" group="1" density="0" mesh="realsense_d435_binary"/>
    <geom size="0.012525 0.045 0.0125" pos="0.17 -0.01 0.8525" type="box"/>
    <geom pos="0 0 0.15" quat="0.707388 0.706825 0 0" type="mesh" contype="0" conaffinity="0" group="1" density="0" mesh="tracer_base_link_no_wheel"/>
    <geom pos="0 0 0.15" quat="0.707388 0.706825 0 0" type="mesh" mesh="tracer_base_link_no_wheel"/>
    <geom pos="0.23 0 0.19" quat="0.000563312 0.000562864 0.706825 0.707388" type="mesh" contype="0" conaffinity="0" group="1" density="0" mesh="livox_mid360"/>
    <geom pos="0.23 0 0.19" quat="0.000563312 0.000562864 0.706825 0.707388" type="mesh" mesh="livox_mid360"/>
    <geom pos="0 0 0.15" quat="0.999688 -0.0249974 0 0" type="mesh" contype="0" conaffinity="0" group="1" density="0" rgba="0.79216 0.81961 0.93333 1" mesh="box1_Link"/>
    <geom pos="0 0 0.15" quat="0.999688 -0.0249974 0 0" type="mesh" rgba="0.79216 0.81961 0.93333 1" mesh="box1_Link"/>
    <geom pos="0 0 0.15" quat="0.999688 -0.0249974 0 0" type="mesh" contype="0" conaffinity="0" group="1" density="0" rgba="0.79216 0.81961 0.93333 1" mesh="box2_Link"/>
    <geom pos="0 0 0.15" quat="0.999688 -0.0249974 0 0" type="mesh" rgba="0.79216 0.81961 0.93333 1" mesh="box2_Link"/>
    <geom pos="0.233 0.3 0.7775" quat="1 0 0 0" type="mesh" contype="0" conaffinity="0" group="1" density="0" rgba="0.75294 0.75294 0.75294 1" mesh="base_link"/>
    <geom pos="0.233 0.3 0.7775" quat="1 0 0 0" type="mesh" rgba="0.75294 0.75294 0.75294 1" mesh="base_link"/>
    <geom pos="0.233 -0.307 0.7775" quat="1 0 0 0" type="mesh" contype="0" conaffinity="0" group="1" density="0" rgba="0.75294 0.75294 0.75294 1" mesh="base_link"/>
    <geom pos="0.233 -0.307 0.7775" quat="1 0 0 0" type="mesh" rgba="0.75294 0.75294 0.75294 1" mesh="base_link"/>
    <geom pos="-0.309 0.307 0.903" quat="1 0 0 0" type="mesh" contype="0" conaffinity="0" group="1" density="0" rgba="0.75294 0.75294 0.75294 1" mesh="base_link"/>
    <geom pos="-0.309 0.307 0.903" quat="1 0 0 0" type="mesh" rgba="0.75294 0.75294 0.75294 1" mesh="base_link"/>
    <geom pos="-0.309 -0.307 0.903" quat="1 0 0 0" type="mesh" contype="0" conaffinity="0" group="1" density="0" rgba="0.75294 0.75294 0.75294 1" mesh="base_link"/>
    <geom pos="-0.309 -0.307 0.903" quat="1 0 0 0" type="mesh" rgba="0.75294 0.75294 0.75294 1" mesh="base_link"/>
    <body name="right_wheel_link" pos="0 -0.17 0.068">
      <inertial pos="0 0 0" quat="0.707107 0.707107 0 0" mass="6" diaginertia="0.7171 0.7171 0.1361"/>
      <joint name="right_wheel" pos="0 0 0" axis="0 1 0"/>
      <geom type="mesh" contype="0" conaffinity="0" group="1" density="0" mesh="tracer_wheel"/>
      <geom type="mesh" mesh="tracer_wheel"/>
    </body>
    <body name="left_wheel_link" pos="0 0.17 0.068" quat="0.000796327 1 0 0">
      <inertial pos="0 0 0" quat="0.707107 0.707107 0 0" mass="6" diaginertia="0.7171 0.7171 0.1361"/>
      <joint name="left_wheel" pos="0 0 0" axis="0 1 0"/>
      <geom type="mesh" contype="0" conaffinity="0" group="1" density="0" mesh="tracer_wheel"/>
      <geom type="mesh" mesh="tracer_wheel"/>
    </body>
    <body name="fl_castor_link" pos="0.18955 0.17 0.111911" quat="0.707388 -0.706825 0 0">
      <inertial pos="0 0 0" quat="0.707107 0.707107 0 0" mass="1" diaginertia="0.7171 0.7171 0.1361"/>
      <joint name="fl_castor_wheel" pos="0 0 0" axis="0 1 0"/>
      <geom type="mesh" contype="0" conaffinity="0" group="1" density="0" mesh="castor_joint"/>
      <body name="fl_wheel_link" pos="-0.0218084 0.067 0">
        <inertial pos="0 0 0" mass="1" diaginertia="0.3131 0.3131 0.1361"/>
        <joint name="fl_wheel" pos="0 0 0" axis="0 0 1"/>
        <geom type="mesh" contype="0" conaffinity="0" group="1" density="0" mesh="castor"/>
        <geom type="mesh" mesh="castor"/>
      </body>
    </body>
    <body name="fr_castor_link" pos="0.18955 -0.17 0.111911" quat="0.707388 -0.706825 0 0">
      <inertial pos="0 0 0" quat="0.707107 0.707107 0 0" mass="1" diaginertia="0.7171 0.7171 0.1361"/>
      <joint name="fr_castor_wheel" pos="0 0 0" axis="0 1 0"/>
      <geom type="mesh" contype="0" conaffinity="0" group="1" density="0" mesh="castor_joint"/>
      <body name="fr_wheel_link" pos="-0.0218084 0.067 0">
        <inertial pos="0 0 0" mass="1" diaginertia="0.3131 0.3131 0.1361"/>
        <joint name="fr_wheel" pos="0 0 0" axis="0 0 1"/>
        <geom type="mesh" contype="0" conaffinity="0" group="1" density="0" mesh="castor"/>
        <geom type="mesh" mesh="castor"/>
      </body>
    </body>
    <body name="rr_castor_link" pos="-0.18955 -0.17 0.111911" quat="0.707388 -0.706825 0 0">
      <inertial pos="0 0 0" quat="0.707107 0.707107 0 0" mass="1" diaginertia="0.7171 0.7171 0.1361"/>
      <joint name="rr_castor_wheel" pos="0 0 0" axis="0 1 0"/>
      <geom type="mesh" contype="0" conaffinity="0" group="1" density="0" mesh="castor_joint"/>
      <body name="rr_wheel_link" pos="-0.0218084 0.067 0">
        <inertial pos="0 0 0" mass="1" diaginertia="0.3131 0.3131 0.1361"/>
        <joint name="rr_wheel" pos="0 0 0" axis="0 0 1"/>
        <geom type="mesh" contype="0" conaffinity="0" group="1" density="0" mesh="castor"/>
        <geom type="mesh" mesh="castor"/>
      </body>
    </body>
    <body name="rl_castor_link" pos="-0.18955 0.17 0.111911" quat="0.707388 -0.706825 0 0">
      <inertial pos="0 0 0" quat="0.707107 0.707107 0 0" mass="1" diaginertia="0.7171 0.7171 0.1361"/>
      <joint name="rl_castor_wheel" pos="0 0 0" axis="0 1 0"/>
      <geom type="mesh" contype="0" conaffinity="0" group="1" density="0" mesh="castor_joint"/>
      <body name="rl_wheel_link" pos="-0.0218084 0.067 0">
        <inertial pos="0 0 0" mass="1" diaginertia="0.3131 0.3131 0.1361"/>
        <joint name="rl_wheel" pos="0 0 0" axis="0 0 1"/>
        <geom type="mesh" contype="0" conaffinity="0" group="1" density="0" mesh="castor"/>
        <geom type="mesh" mesh="castor"/>
      </body>
    </body>
    <body name="fl_link1" pos="0.233 0.3 0.8378">
      <inertial pos="0.00609525 -0.00429682 0.017959" quat="0.680193 0.680193 -0.193229 0.193229" mass="0.0608351" diaginertia="8.61803e-05 6.38197e-05 3e-05"/>
      <joint name="fl_joint1" pos="0 0 0" axis="0 0 1" range="-10 10" actuatorfrcrange="-100 100"/>
      <geom type="mesh" contype="0" conaffinity="0" group="1" density="0" rgba="0.752941 0.752941 0.752941 1" mesh="link1"/>
      <geom type="mesh" rgba="0.752941 0.752941 0.752941 1" mesh="link1"/>
      <body name="fl_link2" pos="0.02 0 0.0402">
        <inertial pos="-0.132382 0.00220381 0.00011179" quat="0 0.706195 0 0.708017" mass="1.07333" diaginertia="0.0160201 0.01596 0.000499897"/>
        <joint name="fl_joint2" pos="0 0 0" axis="0 1 0" range="-10 10" actuatorfrcrange="-100 100"/>
        <geom type="mesh" contype="0" conaffinity="0" group="1" density="0" rgba="0.752941 0.752941 0.752941 1" mesh="link2"/>
        <geom type="mesh" rgba="0.752941 0.752941 0.752941 1" mesh="link2"/>
        <body name="fl_link3" pos="-0.264 0 0" quat="-3.67321e-06 -1 0 0">
          <inertial pos="0.187203 -0.000305676 -0.0514833" quat="0.269626 0.618013 0.251786 0.694238" mass="0.499405" diaginertia="0.00388848 0.00385541 0.000286113"/>
          <joint name="fl_joint3" pos="0 0 0" axis="0 1 0" range="-10 10" actuatorfrcrange="-100 100"/>
          <geom type="mesh" contype="0" conaffinity="0" group="1" density="0" rgba="0.752941 0.752941 0.752941 1" mesh="link3"/>
          <geom type="mesh" rgba="0.752941 0.752941 0.752941 1" mesh="link3"/>
          <body name="fl_link4" pos="0.245 0 -0.056">
            <inertial pos="0.0388885 0.00295169 -0.0353283" quat="0.913916 -0.0752199 0.315785 -0.243679" mass="0.0809713" diaginertia="0.000184798 0.000152076 5.31251e-05"/>
            <joint name="fl_joint4" pos="0 0 0" axis="0 1 0" range="-10 10" actuatorfrcrange="-100 100"/>
            <geom type="mesh" contype="0" conaffinity="0" group="1" density="0" rgba="0.898039 0.917647 0.929412 1" mesh="link4"/>
            <geom type="mesh" rgba="0.898039 0.917647 0.929412 1" mesh="link4"/>
            <body name="fl_link5" pos="0.06575 -0.001 -0.0825">
              <inertial pos="0.00289957 3.15827e-05 0.0526189" quat="0.998829 0 -0.0483866 0" mass="0.602357" diaginertia="0.000724856 0.00069 0.000205144"/>
              <joint name="fl_joint5" pos="0 0 0" axis="0 0 1" range="-10 10" actuatorfrcrange="-100 100"/>
              <geom type="mesh" contype="0" conaffinity="0" group="1" density="0" rgba="0.752941 0.752941 0.752941 1" mesh="link5"/>
              <geom type="mesh" rgba="0.752941 0.752941 0.752941 1" mesh="link5"/>
              <body name="fl_link6" pos="0.02845 0 0.0825" quat="-3.67321e-06 -1 0 0">
                <inertial pos="0.0542255 4.63803e-05 0.0397819" quat="0.99456 -0.00432991 0.104018 0.00352208" mass="1.02624" diaginertia="0.00224638 0.00191815 0.00107759"/>
                <joint name="fl_joint6" pos="0 0 0" axis="1 0 0" range="-10 10" actuatorfrcrange="-100 100"/>
                <geom type="mesh" contype="0" conaffinity="0" group="1" density="0" rgba="0.898039 0.917647 0.929412 1" mesh="link6"/>
                <geom type="mesh" rgba="0.898039 0.917647 0.929412 1" mesh="link6"/>
                <geom pos="0.0749 0 0.0725" quat="0.5 0.5 0.5 0.5" type="mesh" contype="0" conaffinity="0" group="1" density="0" mesh="realsense_d435_binary"/>
                <geom size="0.012525 0.045 0.0125" pos="0.06 0 0.0725" type="box"/>
                <body name="fl_link7" pos="0.073574 0.024629 0">
                  <inertial pos="-0.000327643 -0.00482005 -0.00167541" quat="0.5 0.5 0.5 0.5" mass="0.0484017" diaginertia="2e-05 2e-05 1e-05"/>
                  <joint name="fl_joint7" pos="0 0 0" axis="0 1 0" type="slide" range="0 0.04765" actuatorfrcrange="-100 100"/>
                  <geom type="mesh" contype="0" conaffinity="0" group="1" density="0" rgba="0.898039 0.917647 0.929412 1" mesh="link7"/>
                  <geom type="mesh" rgba="0.898039 0.917647 0.929412 1" mesh="link7"/>
                </body>
                <body name="fl_link8" pos="0.073574 -0.024629 0">
                  <inertial pos="-0.000327644 0.00482005 0.000752973" quat="0.5 0.5 0.5 0.5" mass="0.0484017" diaginertia="2e-05 2e-05 1e-05"/>
                  <joint name="fl_joint8" pos="0 0 0" axis="0 -1 0" type="slide" range="0 0.04765" actuatorfrcrange="-100 100"/>
                  <geom type="mesh" contype="0" conaffinity="0" group="1" density="0" rgba="0.898039 0.917647 0.929412 1" mesh="link8"/>
                  <geom type="mesh" rgba="0.898039 0.917647 0.929412 1" mesh="link8"/>
                </body>
              </body>
            </body>
          </body>
        </body>
      </body>
    </body>
    <body name="fr_link1" pos="0.233 -0.307 0.8378">
      <inertial pos="0.00609525 -0.00429682 0.017959" quat="0.680193 0.680193 -0.193229 0.193229" mass="0.0608351" diaginertia="8.61803e-05 6.38197e-05 3e-05"/>
      <joint name="fr_joint1" pos="0 0 0" axis="0 0 1" range="-10 10" actuatorfrcrange="-100 100"/>
      <geom type="mesh" contype="0" conaffinity="0" group="1" density="0" rgba="0.752941 0.752941 0.752941 1" mesh="link1"/>
      <geom type="mesh" rgba="0.752941 0.752941 0.752941 1" mesh="link1"/>
      <body name="fr_link2" pos="0.02 0 0.0402">
        <inertial pos="-0.132382 0.00220381 0.00011179" quat="0 0.706195 0 0.708017" mass="1.07333" diaginertia="0.0160201 0.01596 0.000499897"/>
        <joint name="fr_joint2" pos="0 0 0" axis="0 1 0" range="-10 10" actuatorfrcrange="-100 100"/>
        <geom type="mesh" contype="0" conaffinity="0" group="1" density="0" rgba="0.752941 0.752941 0.752941 1" mesh="link2"/>
        <geom type="mesh" rgba="0.752941 0.752941 0.752941 1" mesh="link2"/>
        <body name="fr_link3" pos="-0.264 0 0" quat="-3.67321e-06 -1 0 0">
          <inertial pos="0.187203 -0.000305676 -0.0514833" quat="0.269626 0.618013 0.251786 0.694238" mass="0.499405" diaginertia="0.00388848 0.00385541 0.000286113"/>
          <joint name="fr_joint3" pos="0 0 0" axis="0 1 0" range="-10 10" actuatorfrcrange="-100 100"/>
          <geom type="mesh" contype="0" conaffinity="0" group="1" density="0" rgba="0.752941 0.752941 0.752941 1" mesh="link3"/>
          <geom type="mesh" rgba="0.752941 0.752941 0.752941 1" mesh="link3"/>
          <body name="fr_link4" pos="0.245 0 -0.056">
            <inertial pos="0.0388885 0.00295169 -0.0353283" quat="0.913916 -0.0752199 0.315785 -0.243679" mass="0.0809713" diaginertia="0.000184798 0.000152076 5.31251e-05"/>
            <joint name="fr_joint4" pos="0 0 0" axis="0 1 0" range="-10 10" actuatorfrcrange="-100 100"/>
            <geom type="mesh" contype="0" conaffinity="0" group="1" density="0" rgba="0.898039 0.917647 0.929412 1" mesh="link4"/>
            <geom type="mesh" rgba="0.898039 0.917647 0.929412 1" mesh="link4"/>
            <body name="fr_link5" pos="0.06575 -0.001 -0.0825">
              <inertial pos="0.00289957 3.15827e-05 0.0526189" quat="0.998829 0 -0.0483866 0" mass="0.602357" diaginertia="0.000724856 0.00069 0.000205144"/>
              <joint name="fr_joint5" pos="0 0 0" axis="0 0 1" range="-10 10" actuatorfrcrange="-100 100"/>
              <geom type="mesh" contype="0" conaffinity="0" group="1" density="0" rgba="0.752941 0.752941 0.752941 1" mesh="link5"/>
              <geom type="mesh" rgba="0.752941 0.752941 0.752941 1" mesh="link5"/>
              <body name="fr_link6" pos="0.02845 0 0.0825" quat="-3.67321e-06 -1 0 0">
                <inertial pos="0.0542255 4.63803e-05 0.0397819" quat="0.99456 -0.00432991 0.104018 0.00352208" mass="1.02624" diaginertia="0.00224638 0.00191815 0.00107759"/>
                <joint name="fr_joint6" pos="0 0 0" axis="1 0 0" range="-10 10" actuatorfrcrange="-100 100"/>
                <geom type="mesh" contype="0" conaffinity="0" group="1" density="0" rgba="0.898039 0.917647 0.929412 1" mesh="link6"/>
                <geom type="mesh" rgba="0.898039 0.917647 0.929412 1" mesh="link6"/>
                <geom pos="0.0749 0 0.0725" quat="0.5 0.5 0.5 0.5" type="mesh" contype="0" conaffinity="0" group="1" density="0" mesh="realsense_d435_binary"/>
                <geom size="0.012525 0.045 0.0125" pos="0.06 0 0.0725" type="box"/>
                <body name="fr_link7" pos="0.073574 0.024629 0">
                  <inertial pos="-0.000327643 -0.00482005 -0.00167541" quat="0.5 0.5 0.5 0.5" mass="0.0484017" diaginertia="2e-05 2e-05 1e-05"/>
                  <joint name="fr_joint7" pos="0 0 0" axis="0 1 0" type="slide" range="0 0.04765" actuatorfrcrange="-100 100"/>
                  <geom type="mesh" contype="0" conaffinity="0" group="1" density="0" rgba="0.898039 0.917647 0.929412 1" mesh="link7"/>
                  <geom type="mesh" rgba="0.898039 0.917647 0.929412 1" mesh="link7"/>
                </body>
                <body name="fr_link8" pos="0.073574 -0.024629 0">
                  <inertial pos="-0.000327644 0.00482005 0.000752973" quat="0.5 0.5 0.5 0.5" mass="0.0484017" diaginertia="2e-05 2e-05 1e-05"/>
                  <joint name="fr_joint8" pos="0 0 0" axis="0 -1 0" type="slide" range="0 0.04765" actuatorfrcrange="-100 100"/>
                  <geom type="mesh" contype="0" conaffinity="0" group="1" density="0" rgba="0.898039 0.917647 0.929412 1" mesh="link8"/>
                  <geom type="mesh" rgba="0.898039 0.917647 0.929412 1" mesh="link8"/>
                </body>
              </body>
            </body>
          </body>
        </body>
      </body>
    </body>
    <body name="lr_link1" pos="-0.309 0.307 0.9633">
      <inertial pos="0.00609525 -0.00429682 0.017959" quat="0.680193 0.680193 -0.193229 0.193229" mass="0.0608351" diaginertia="8.61803e-05 6.38197e-05 3e-05"/>
      <joint name="lr_joint1" pos="0 0 0" axis="0 0 1" range="-10 10" actuatorfrcrange="-100 100"/>
      <geom type="mesh" contype="0" conaffinity="0" group="1" density="0" rgba="0.752941 0.752941 0.752941 1" mesh="link1"/>
      <geom type="mesh" rgba="0.752941 0.752941 0.752941 1" mesh="link1"/>
      <body name="lr_link2" pos="0.02 0 0.0402">
        <inertial pos="-0.132382 0.00220381 0.00011179" quat="0 0.706195 0 0.708017" mass="1.07333" diaginertia="0.0160201 0.01596 0.000499897"/>
        <joint name="lr_joint2" pos="0 0 0" axis="0 1 0" range="-10 10" actuatorfrcrange="-100 100" frictionloss="100"/>
        <geom type="mesh" contype="0" conaffinity="0" group="1" density="0" rgba="0.752941 0.752941 0.752941 1" mesh="link2"/>
        <geom type="mesh" rgba="0.752941 0.752941 0.752941 1" mesh="link2"/>
        <body name="lr_link3" pos="-0.264 0 0" quat="-3.67321e-06 -1 0 0">
          <inertial pos="0.187203 -0.000305676 -0.0514833" quat="0.269626 0.618013 0.251786 0.694238" mass="0.499405" diaginertia="0.00388848 0.00385541 0.000286113"/>
          <joint name="lr_joint3" pos="0 0 0" axis="0 1 0" range="-10 10" actuatorfrcrange="-100 100" frictionloss="100"/>
          <geom type="mesh" contype="0" conaffinity="0" group="1" density="0" rgba="0.752941 0.752941 0.752941 1" mesh="link3"/>
          <geom type="mesh" rgba="0.752941 0.752941 0.752941 1" mesh="link3"/>
          <body name="lr_link4" pos="0.245 0 -0.056">
            <inertial pos="0.0388885 0.00295169 -0.0353283" quat="0.913916 -0.0752199 0.315785 -0.243679" mass="0.0809713" diaginertia="0.000184798 0.000152076 5.31251e-05"/>
            <joint name="lr_joint4" pos="0 0 0" axis="0 1 0" range="-10 10" actuatorfrcrange="-100 100"/>
            <geom type="mesh" contype="0" conaffinity="0" group="1" density="0" rgba="0.898039 0.917647 0.929412 1" mesh="link4"/>
            <geom type="mesh" rgba="0.898039 0.917647 0.929412 1" mesh="link4"/>
            <body name="lr_link5" pos="0.06575 -0.001 -0.0825">
              <inertial pos="0.00289957 3.15827e-05 0.0526189" quat="0.998829 0 -0.0483866 0" mass="0.602357" diaginertia="0.000724856 0.00069 0.000205144"/>
              <joint name="lr_joint5" pos="0 0 0" axis="0 0 1" range="-10 10" actuatorfrcrange="-100 100"/>
              <geom type="mesh" contype="0" conaffinity="0" group="1" density="0" rgba="0.752941 0.752941 0.752941 1" mesh="link5"/>
              <geom type="mesh" rgba="0.752941 0.752941 0.752941 1" mesh="link5"/>
              <body name="lr_link6" pos="0.02845 0 0.0825" quat="-3.67321e-06 -1 0 0">
                <inertial pos="0.0471798 0.00010297 -0.000138511" quat="0.495436 0.504523 -0.504523 0.495436" mass="0.462245" diaginertia="0.000910182 0.00068 0.000359818"/>
                <joint name="lr_joint6" pos="0 0 0" axis="1 0 0" range="-10 10" actuatorfrcrange="-100 100"/>
                <geom type="mesh" contype="0" conaffinity="0" group="1" density="0" rgba="0.898039 0.917647 0.929412 1" mesh="link6"/>
                <geom type="mesh" rgba="0.898039 0.917647 0.929412 1" mesh="link6"/>
                <body name="lr_link7" pos="0.073574 0.024629 0">
                  <inertial pos="-0.000327643 -0.00482005 -0.00167541" quat="0.5 0.5 0.5 0.5" mass="0.0484017" diaginertia="2e-05 2e-05 1e-05"/>
                  <joint name="lr_joint7" pos="0 0 0" axis="0 1 0" type="slide" range="0 0.04765" actuatorfrcrange="-100 100"/>
                  <geom type="mesh" contype="0" conaffinity="0" group="1" density="0" rgba="0.898039 0.917647 0.929412 1" mesh="link7"/>
                  <geom type="mesh" rgba="0.898039 0.917647 0.929412 1" mesh="link7"/>
                </body>
                <body name="lr_link8" pos="0.073574 -0.024629 0">
                  <inertial pos="-0.000327644 0.00482005 0.000752973" quat="0.5 0.5 0.5 0.5" mass="0.0484017" diaginertia="2e-05 2e-05 1e-05"/>
                  <joint name="lr_joint8" pos="0 0 0" axis="0 -1 0" type="slide" range="0 0.04765" actuatorfrcrange="-100 100"/>
                  <geom type="mesh" contype="0" conaffinity="0" group="1" density="0" rgba="0.898039 0.917647 0.929412 1" mesh="link8"/>
                  <geom type="mesh" rgba="0.898039 0.917647 0.929412 1" mesh="link8"/>
                </body>
              </body>
            </body>
          </body>
        </body>
      </body>
    </body>
    <body name="rr_link1" pos="-0.309 -0.307 0.9633">
      <inertial pos="0.00609525 -0.00429682 0.017959" quat="0.680193 0.680193 -0.193229 0.193229" mass="0.0608351" diaginertia="8.61803e-05 6.38197e-05 3e-05"/>
      <joint name="rr_joint1" pos="0 0 0" axis="0 0 1" range="-10 10" actuatorfrcrange="-100 100"/>
      <geom type="mesh" contype="0" conaffinity="0" group="1" density="0" rgba="0.752941 0.752941 0.752941 1" mesh="link1"/>
      <geom type="mesh" rgba="0.752941 0.752941 0.752941 1" mesh="link1"/>
      <body name="rr_link2" pos="0.02 0 0.0402">
        <inertial pos="-0.132382 0.00220381 0.00011179" quat="0 0.706195 0 0.708017" mass="1.07333" diaginertia="0.0160201 0.01596 0.000499897"/>
        <joint name="rr_joint2" pos="0 0 0" axis="0 1 0" range="-10 10" actuatorfrcrange="-100 100"/>
        <geom type="mesh" contype="0" conaffinity="0" group="1" density="0" rgba="0.752941 0.752941 0.752941 1" mesh="link2"/>
        <geom type="mesh" rgba="0.752941 0.752941 0.752941 1" mesh="link2"/>
        <body name="rr_link3" pos="-0.264 0 0" quat="-3.67321e-06 -1 0 0">
          <inertial pos="0.187203 -0.000305676 -0.0514833" quat="0.269626 0.618013 0.251786 0.694238" mass="0.499405" diaginertia="0.00388848 0.00385541 0.000286113"/>
          <joint name="rr_joint3" pos="0 0 0" axis="0 1 0" range="-10 10" actuatorfrcrange="-100 100"/>
          <geom type="mesh" contype="0" conaffinity="0" group="1" density="0" rgba="0.752941 0.752941 0.752941 1" mesh="link3"/>
          <geom type="mesh" rgba="0.752941 0.752941 0.752941 1" mesh="link3"/>
          <body name="rr_link4" pos="0.245 0 -0.056">
            <inertial pos="0.0388885 0.00295169 -0.0353283" quat="0.913916 -0.0752199 0.315785 -0.243679" mass="0.0809713" diaginertia="0.000184798 0.000152076 5.31251e-05"/>
            <joint name="rr_joint4" pos="0 0 0" axis="0 1 0" range="-10 10" actuatorfrcrange="-100 100"/>
            <geom type="mesh" contype="0" conaffinity="0" group="1" density="0" rgba="0.898039 0.917647 0.929412 1" mesh="link4"/>
            <geom type="mesh" rgba="0.898039 0.917647 0.929412 1" mesh="link4"/>
            <body name="rr_link5" pos="0.06575 -0.001 -0.0825">
              <inertial pos="0.00289957 3.15827e-05 0.0526189" quat="0.998829 0 -0.0483866 0" mass="0.602357" diaginertia="0.000724856 0.00069 0.000205144"/>
              <joint name="rr_joint5" pos="0 0 0" axis="0 0 1" range="-10 10" actuatorfrcrange="-100 100"/>
              <geom type="mesh" contype="0" conaffinity="0" group="1" density="0" rgba="0.752941 0.752941 0.752941 1" mesh="link5"/>
              <geom type="mesh" rgba="0.752941 0.752941 0.752941 1" mesh="link5"/>
              <body name="rr_link6" pos="0.02845 0 0.0825" quat="-3.67321e-06 -1 0 0">
                <inertial pos="0.0471798 0.00010297 -0.000138511" quat="0.495436 0.504523 -0.504523 0.495436" mass="0.462245" diaginertia="0.000910182 0.00068 0.000359818"/>
                <joint name="rr_joint6" pos="0 0 0" axis="1 0 0" range="-10 10" actuatorfrcrange="-100 100"/>
                <geom type="mesh" contype="0" conaffinity="0" group="1" density="0" rgba="0.898039 0.917647 0.929412 1" mesh="link6"/>
                <geom type="mesh" rgba="0.898039 0.917647 0.929412 1" mesh="link6"/>
                <body name="rr_link7" pos="0.073574 0.024629 0">
                  <inertial pos="-0.000327643 -0.00482005 -0.00167541" quat="0.5 0.5 0.5 0.5" mass="0.0484017" diaginertia="2e-05 2e-05 1e-05"/>
                  <joint name="rr_joint7" pos="0 0 0" axis="0 1 0" type="slide" range="0 0.04765" actuatorfrcrange="-100 100"/>
                  <geom type="mesh" contype="0" conaffinity="0" group="1" density="0" rgba="0.898039 0.917647 0.929412 1" mesh="link7"/>
                  <geom type="mesh" rgba="0.898039 0.917647 0.929412 1" mesh="link7"/>
                </body>
                <body name="rr_link8" pos="0.073574 -0.024629 0">
                  <inertial pos="-0.000327644 0.00482005 0.000752973" quat="0.5 0.5 0.5 0.5" mass="0.0484017" diaginertia="2e-05 2e-05 1e-05"/>
                  <joint name="rr_joint8" pos="0 0 0" axis="0 -1 0" type="slide" range="0 0.04765" actuatorfrcrange="-100 100"/>
                  <geom type="mesh" contype="0" conaffinity="0" group="1" density="0" rgba="0.898039 0.917647 0.929412 1" mesh="link8"/>
                  <geom type="mesh" rgba="0.898039 0.917647 0.929412 1" mesh="link8"/>
                </body>
              </body>
            </body>
          </body>
        </body>
      </body>
    </body>
  </worldbody>
</mujoco>
